Workbook

Sheet Command Dashboard
A1: SURGE COMMAND CENTER
A2: Executive Dashboard — Updated 20 April 2026 15:54 CDT
A4: HEADCOUNT | D4: PIPELINE ACTIVE | G4: CLEARANCES COMPLETE | J4: EQUIP FULFILLED | M4: TRAINING COMPLETE
A5: =COUNTIF('Employee Roster'!M3:M22,"Deployed")+COUNTIF('Employee Roster'!M3:M22,"Training")+COUNTIF('Employee Roster'!M3:M22,"Nesting")+COUNTIF('Employee Roster'!M3:M22,"Onboarding") | D5: =COUNTIF('Candidate Pipeline'!W3:W22,"Sourced")+COUNTIF('Candidate Pipeline'!W3:W22,"Screened")+COUNTIF('Candidate Pipeline'!W3:W22,"Interviewed")+COUNTIF('Candidate Pipeline'!W3:W22,"Offered")+COUNTIF('Candidate Pipeline'!W3:W22,"Accepted")+COUNTIF('Candidate Pipeline'!W3:W22,"Onboarding") | G5: =COUNTIF('E-QIP Tracker'!Y3:Y17,"Complete") | J5: =COUNTIF('Employee Roster'!R3:R22,"Y") | M5: =COUNTIF('Employee Roster'!V3:V22,"Complete")
A6: Target: 35 | D6: Candidates in Funnel | G6: Of 15 Tracked | J6: Delivered & Verified | M6: Personnel Trained
A8: QA AVG SCORE | D8: ATTRITION RATE | G8: OPEN RISKS | J8: CHECKLIST DONE | M8: ALERTS OPEN
A9: =ROUND(AVERAGE('QA Monitoring'!N3:N27),1) | D9: =IF(COUNTA('Employee Roster'!A3:A22)=0,0,COUNTIF('Employee Roster'!M3:M22,"Separated")/COUNTA('Employee Roster'!A3:A22)) | G9: =COUNTIF('Risk Register'!K3:K22,"Open")+COUNTIF('Risk Register'!K3:K22,"Mitigating") | J9: =IF(COUNTA('Surge Checklist'!A3:A47)=0,0,COUNTIF('Surge Checklist'!H3:H47,"Complete")/COUNTA('Surge Checklist'!A3:A47)) | M9: =COUNTIF(Alerts!H3:H17,"Open")
A10: Across All Monitored | D10: Separations / Hired | G10: Active Risk Items | J10: Tasks Complete % | M10: Action Items Pending
A12: PIPELINE FUNNEL DATA | D12: CLEARANCE STATUS DATA | G12: HEADCOUNT RAMP-UP | K12: RISK HEAT MAP DATA
A13: Sourced | B13: =COUNTIF('Candidate Pipeline'!W3:W22,A13) | D13: Complete | E13: =COUNTIF('E-QIP Tracker'!Y3:Y17,D13) | G13: Week | H13: Actual | I13: Target | K13: Risk Level | L13: Count | M13: Avg Score | N13: Max Score
A14: Screened | B14: =COUNTIF('Candidate Pipeline'!W3:W22,A14) | D14: Investigation | E14: =COUNTIF('E-QIP Tracker'!Y3:Y17,D14) | G14: Pre-Surge | H14: 3 | I14: 3 | K14: Critical | L14: =COUNTIF('Risk Register'!G3:G22,K14) | M14: =IFERROR(AVERAGEIF('Risk Register'!G3:G22,K14,'Risk Register'!F3:F22),0) | N14: =IFERROR(MAXIFS('Risk Register'!F3:F22,'Risk Register'!G3:G22,K14),0)
A15: Interviewed | B15: =COUNTIF('Candidate Pipeline'!W3:W22,A15) | D15: Submitted | E15: =COUNTIF('E-QIP Tracker'!Y3:Y17,D15) | G15: Week 1 | H15: 10 | I15: 12 | K15: High | L15: =COUNTIF('Risk Register'!G3:G22,K15) | M15: =IFERROR(AVERAGEIF('Risk Register'!G3:G22,K15,'Risk Register'!F3:F22),0) | N15: =IFERROR(MAXIFS('Risk Register'!F3:F22,'Risk Register'!G3:G22,K15),0)
A16: Offered | B16: =COUNTIF('Candidate Pipeline'!W3:W22,A16) | D16: Interim Pending | E16: =COUNTIF('E-QIP Tracker'!Y3:Y17,D16) | G16: Week 2 | H16: 18 | I16: 20 | K16: Medium | L16: =COUNTIF('Risk Register'!G3:G22,K16) | M16: =IFERROR(AVERAGEIF('Risk Register'!G3:G22,K16,'Risk Register'!F3:F22),0) | N16: =IFERROR(MAXIFS('Risk Register'!F3:F22,'Risk Register'!G3:G22,K16),0)
A17: Accepted | B17: =COUNTIF('Candidate Pipeline'!W3:W22,A17) | D17: Account Created | E17: =COUNTIF('E-QIP Tracker'!Y3:Y17,D17) | G17: Week 3 | H17: 25 | I17: 28 | K17: Low | L17: =COUNTIF('Risk Register'!G3:G22,K17) | M17: =IFERROR(AVERAGEIF('Risk Register'!G3:G22,K17,'Risk Register'!F3:F22),0) | N17: =IFERROR(MAXIFS('Risk Register'!F3:F22,'Risk Register'!G3:G22,K17),0)
A18: Onboarding | B18: =COUNTIF('Candidate Pipeline'!W3:W22,A18) | D18: Not Started | E18: =COUNTIF('E-QIP Tracker'!Y3:Y17,D18) | G18: Week 4 (Plan) | H18: 32 | I18: 35
A19: Deployed | B19: =COUNTIF('Candidate Pipeline'!W3:W22,A19)
A21: QA SCORE DISTRIBUTION
A22: 90-100 (Excellent) | B22: =COUNTIFS('QA Monitoring'!N3:N27,">=90")
A23: 80-89 (Good) | B23: =COUNTIFS('QA Monitoring'!N3:N27,">=80",'QA Monitoring'!N3:N27,"<90")
A24: 70-79 (Needs Improvement) | B24: =COUNTIFS('QA Monitoring'!N3:N27,">=70",'QA Monitoring'!N3:N27,"<80")
A25: Below 70 (Failing) | B25: =COUNTIFS('QA Monitoring'!N3:N27,"<70")

Sheet Surge Checklist
A1: SURGE CHECKLIST — Day 0-30 Task Tracker
A2: Phase | B2: Task # | C2: Section | D2: Task Description | E2: Owner | F2: Due Date | G2: Completion Date | H2: Status | I2: Priority | J2: Dependencies | K2: Days Until Due
A3: Pre-Surge | B3: T-001 | C3: Workforce Planning | D3: Finalize surge headcount requirements and labor categories | E3: Program Manager | F3: 46113 | G3: 46113 | H3: Complete | I3: Critical | K3: =IF(OR(F3="",H3="Complete"),"",F3-TODAY())
A4: Pre-Surge | B4: T-002 | C4: Workforce Planning | D4: Submit staffing plan to contracting officer for approval | E4: Program Manager | F4: 46114 | G4: 46114 | H4: Complete | I4: Critical | J4: T-001 | K4: =IF(OR(F4="",H4="Complete"),"",F4-TODAY())
A5: Pre-Surge | B5: T-003 | C5: Workforce Planning | D5: Define remote work policies and telework agreements | E5: HR Manager | F5: 46115 | G5: 46115 | H5: Complete | I5: High | K5: =IF(OR(F5="",H5="Complete"),"",F5-TODAY())
A6: Pre-Surge | B6: T-004 | C6: Recruiting | D6: Post all surge positions on approved job boards | E6: Recruiting Lead | F6: 46115 | G6: 46115 | H6: Complete | I6: Critical | J6: T-001 | K6: =IF(OR(F6="",H6="Complete"),"",F6-TODAY())
A7: Pre-Surge | B7: T-005 | C7: Recruiting | D7: Activate staffing agency contracts for contingent hiring | E7: Recruiting Lead | F7: 46116 | G7: 46116 | H7: Complete | I7: High | K7: =IF(OR(F7="",H7="Complete"),"",F7-TODAY())
A8: Pre-Surge | B8: T-006 | C8: Security & Compliance | D8: Submit SAAR forms for all anticipated system access | E8: FSO/Security | F8: 46117 | G8: 46116 | H8: Complete | I8: Critical | K8: =IF(OR(F8="",H8="Complete"),"",F8-TODAY())
A9: Pre-Surge | B9: T-007 | C9: IT & Equipment | D9: Order laptops and peripherals for first cohort (20 units) | E9: IT Lead | F9: 46117 | G9: 46117 | H9: Complete | I9: Critical | J9: T-001 | K9: =IF(OR(F9="",H9="Complete"),"",F9-TODAY())
A10: Pre-Surge | B10: T-008 | C10: IT & Equipment | D10: Provision VPN accounts and MFA tokens | E10: IT Lead | F10: 46118 | G10: 46118 | H10: Complete | I10: Critical | K10: =IF(OR(F10="",H10="Complete"),"",F10-TODAY())
A11: Pre-Surge | B11: T-009 | C11: Training | D11: Develop virtual training curriculum and LMS modules | E11: Training Lead | F11: 46118 | G11: 46117 | H11: Complete | I11: High | K11: =IF(OR(F11="",H11="Complete"),"",F11-TODAY())
A12: Pre-Surge | B12: T-010 | C12: HR & Onboarding | D12: Prepare onboarding packets and welcome emails | E12: HR Manager | F12: 46119 | G12: 46119 | H12: Complete | I12: Medium | K12: =IF(OR(F12="",H12="Complete"),"",F12-TODAY())
A13: Day 0-1 | B13: T-011 | C13: Recruiting | D13: Screen and schedule phone interviews for first cohort | E13: Recruiting Lead | F13: 46120 | G13: 46120 | H13: Complete | I13: Critical | J13: T-004 | K13: =IF(OR(F13="",H13="Complete"),"",F13-TODAY())
A14: Day 0-1 | B14: T-012 | C14: Security & Compliance | D14: Initiate eQIP accounts for cleared positions | E14: FSO/Security | F14: 46120 | G14: 46120 | H14: Complete | I14: Critical | K14: =IF(OR(F14="",H14="Complete"),"",F14-TODAY())
A15: Day 0-1 | B15: T-013 | C15: IT & Equipment | D15: Ship equipment to first cohort remote locations | E15: IT Lead | F15: 46121 | G15: 46121 | H15: Complete | I15: Critical | J15: T-007 | K15: =IF(OR(F15="",H15="Complete"),"",F15-TODAY())
A16: Day 0-1 | B16: T-014 | C16: HR & Onboarding | D16: Conduct virtual Day 1 orientation sessions | E16: HR Manager | F16: 46121 | G16: 46121 | H16: Complete | I16: High | J16: T-010 | K16: =IF(OR(F16="",H16="Complete"),"",F16-TODAY())
A17: Day 0-1 | B17: T-015 | C17: Training | D17: Launch online security awareness training | E17: Training Lead | F17: 46121 | G17: 46120 | H17: Complete | I17: Critical | J17: T-009 | K17: =IF(OR(F17="",H17="Complete"),"",F17-TODAY())
A18: Day 2-3 | B18: T-016 | C18: Recruiting | D18: Complete first-round interviews for Cohort 1 | E18: Recruiting Lead | F18: 46122 | G18: 46122 | H18: Complete | I18: High | J18: T-011 | K18: =IF(OR(F18="",H18="Complete"),"",F18-TODAY())
A19: Day 2-3 | B19: T-017 | C19: Security & Compliance | D19: Collect OF-306 forms from all new hires | E19: FSO/Security | F19: 46122 | G19: 46122 | H19: Complete | I19: Critical | K19: =IF(OR(F19="",H19="Complete"),"",F19-TODAY())
A20: Day 2-3 | B20: T-018 | C20: IT & Equipment | D20: Verify remote workspace attestation forms | E20: IT Lead | F20: 46123 | G20: 46123 | H20: Complete | I20: High | J20: T-013 | K20: =IF(OR(F20="",H20="Complete"),"",F20-TODAY())
A21: Day 2-3 | B21: T-019 | C21: Training | D21: Begin role-specific virtual training modules | E21: Training Lead | F21: 46123 | G21: 46123 | H21: Complete | I21: High | J21: T-015 | K21: =IF(OR(F21="",H21="Complete"),"",F21-TODAY())
A22: Day 2-3 | B22: T-020 | C22: Quality | D22: Establish QA monitoring schedule and rubrics | E22: QA Lead | F22: 46123 | G22: 46122 | H22: Complete | I22: High | K22: =IF(OR(F22="",H22="Complete"),"",F22-TODAY())
A23: Day 4-7 | B23: T-021 | C23: Recruiting | D23: Extend offers to qualified Cohort 1 candidates | E23: Recruiting Lead | F23: 46125 | G23: 46124 | H23: Complete | I23: Critical | J23: T-016 | K23: =IF(OR(F23="",H23="Complete"),"",F23-TODAY())
A24: Day 4-7 | B24: T-022 | C24: Security & Compliance | D24: Schedule fingerprint appointments for all new hires | E24: FSO/Security | F24: 46125 | G24: 46125 | H24: Complete | I24: High | J24: T-017 | K24: =IF(OR(F24="",H24="Complete"),"",F24-TODAY())
A25: Day 4-7 | B25: T-023 | C25: IT & Equipment | D25: Confirm VPN connectivity for all deployed staff | E25: IT Lead | F25: 46126 | G25: 46126 | H25: Complete | I25: Critical | J25: T-008 | K25: =IF(OR(F25="",H25="Complete"),"",F25-TODAY())
A26: Day 4-7 | B26: T-024 | C26: Training | D26: Administer training knowledge checks | E26: Training Lead | F26: 46126 | G26: 46126 | H26: Complete | I26: Medium | J26: T-019 | K26: =IF(OR(F26="",H26="Complete"),"",F26-TODAY())
A27: Day 4-7 | B27: T-025 | C27: HR & Onboarding | D27: Complete I-9 verification for all new hires | E27: HR Manager | F27: 46126 | G27: 46125 | H27: Complete | I27: Critical | K27: =IF(OR(F27="",H27="Complete"),"",F27-TODAY())
A28: Day 4-7 | B28: T-026 | C28: Quality | D28: Conduct first round of live QA monitoring | E28: QA Lead | F28: 46127 | G28: 46127 | H28: Complete | I28: High | J28: T-020 | K28: =IF(OR(F28="",H28="Complete"),"",F28-TODAY())
A29: Day 4-7 | B29: T-027 | C29: Workforce Planning | D29: Review ramp progress against staffing plan | E29: Program Manager | F29: 46127 | G29: 46127 | H29: Complete | I29: High | K29: =IF(OR(F29="",H29="Complete"),"",F29-TODAY())
A30: Week 2 | B30: T-028 | C30: Recruiting | D30: Source and screen Cohort 2 candidates | E30: Recruiting Lead | F30: 46129 | G30: 46129 | H30: Complete | I30: High | K30: =IF(OR(F30="",H30="Complete"),"",F30-TODAY())
A31: Week 2 | B31: T-029 | C31: Security & Compliance | D31: Submit interim clearance requests for priority roles | E31: FSO/Security | F31: 46129 | G31: 46129 | H31: Complete | I31: Critical | J31: T-012 | K31: =IF(OR(F31="",H31="Complete"),"",F31-TODAY())
A32: Week 2 | B32: T-030 | C32: IT & Equipment | D32: Order equipment for Cohort 2 (15 units) | E32: IT Lead | F32: 46130 | G32: 46130 | H32: Complete | I32: High | K32: =IF(OR(F32="",H32="Complete"),"",F32-TODAY())
A33: Week 2 | B33: T-031 | C33: Training | D33: Transition Cohort 1 from training to nesting | E33: Training Lead | F33: 46130 | G33: 46130 | H33: Complete | I33: High | J33: T-024 | K33: =IF(OR(F33="",H33="Complete"),"",F33-TODAY())
A34: Week 2 | B34: T-032 | C34: HR & Onboarding | D34: Conduct 7-day check-in surveys for Cohort 1 | E34: HR Manager | F34: 46131 | G34: 46131 | H34: Complete | I34: Medium | K34: =IF(OR(F34="",H34="Complete"),"",F34-TODAY())
A35: Week 2 | B35: T-033 | C35: Quality | D35: Calibrate QA scoring across evaluators | E35: QA Lead | F35: 46131 | H35: In Progress | I35: High | J35: T-026 | K35: =IF(OR(F35="",H35="Complete"),"",F35-TODAY())
A36: Week 2 | B36: T-034 | C36: Workforce Planning | D36: Update attrition risk assessment | E36: Program Manager | F36: 46132 | H36: In Progress | I36: Medium | K36: =IF(OR(F36="",H36="Complete"),"",F36-TODAY())
A37: Week 3-4 | B37: T-035 | C37: Recruiting | D37: Complete interviews and offers for Cohort 2 | E37: Recruiting Lead | F37: 46136 | H37: In Progress | I37: High | J37: T-028 | K37: =IF(OR(F37="",H37="Complete"),"",F37-TODAY())
A38: Week 3-4 | B38: T-036 | C38: Security & Compliance | D38: Track eQIP submission compliance — target 100% | E38: FSO/Security | F38: 46136 | H38: In Progress | I38: Critical | J38: T-029 | K38: =IF(OR(F38="",H38="Complete"),"",F38-TODAY())
A39: Week 3-4 | B39: T-037 | C39: IT & Equipment | D39: Ship and verify equipment for Cohort 2 | E39: IT Lead | F39: 46137 | H39: Not Started | I39: High | J39: T-030 | K39: =IF(OR(F39="",H39="Complete"),"",F39-TODAY())
A40: Week 3-4 | B40: T-038 | C40: Training | D40: Begin Cohort 2 virtual training | E40: Training Lead | F40: 46137 | H40: Not Started | I40: High | J40: T-035 | K40: =IF(OR(F40="",H40="Complete"),"",F40-TODAY())
...

Sheet Candidate Pipeline
A1: CANDIDATE PIPELINE
A2: Candidate ID | B2: First Name | C2: Last Name | D2: Source | E2: Date Sourced | F2: Position Title | G2: Labor Category | H2: Clearance Required | I2: Recruiter | J2: Phone Screen Date | K2: Phone Screen Result | L2: Interview Date | M2: Interviewer(s) | N2: Interview Score | O2: Interview Result | P2: Offer Extended Date | Q2: Offer Amount | R2: Offer Accepted | S2: Offer Accept Date | T2: Background Check Status | U2: Drug Test Status | V2: Start Date | W2: Pipeline Stage | X2: Days in Current Stage | Y2: Withdrawal Reason | Z2: Notes
A3: C-001 | B3: Maria | C3: Santos | D3: Job Board | E3: 46106 | F3: Case Analyst | G3: Analyst | H3: Public Trust | I3: J. Rivera | J3: 46108 | K3: Pass | L3: 46111 | M3: T. Washington | N3: 4.2 | O3: Pass | P3: 46114 | Q3: 72000 | R3: Y | S3: 46115 | T3: Clear | U3: Pass | V3: 46121 | W3: Deployed | X3: =IF(V3<>"",TODAY()-V3,IF(S3<>"",TODAY()-S3,IF(P3<>"",TODAY()-P3,IF(L3<>"",TODAY()-L3,IF(J3<>"",TODAY()-J3,IF(E3<>"",TODAY()-E3,""))))))
A4: C-002 | B4: James | C4: Mitchell | D4: Referral | E4: 46107 | F4: Program Support | G4: Admin | H4: Public Trust | I4: S. Patel | J4: 46109 | K4: Pass | L4: 46112 | M4: L. Chen | N4: 3.8 | O4: Pass | P4: 46115 | Q4: 65000 | R4: Y | S4: 46116 | T4: Clear | U4: Pass | V4: 46122 | W4: Deployed | X4: =IF(V4<>"",TODAY()-V4,IF(S4<>"",TODAY()-S4,IF(P4<>"",TODAY()-P4,IF(L4<>"",TODAY()-L4,IF(J4<>"",TODAY()-J4,IF(E4<>"",TODAY()-E4,""))))))
A5: C-003 | B5: Aisha | C5: Johnson | D5: Staffing Agency | E5: 46108 | F5: IT Support Spec | G5: IT | H5: Secret | I5: J. Rivera | J5: 46110 | K5: Pass | L5: 46113 | M5: M. Kim | N5: 4.5 | O5: Pass | P5: 46116 | Q5: 85000 | R5: Y | S5: 46117 | T5: Clear | U5: Pass | V5: 46123 | W5: Deployed | X5: =IF(V5<>"",TODAY()-V5,IF(S5<>"",TODAY()-S5,IF(P5<>"",TODAY()-P5,IF(L5<>"",TODAY()-L5,IF(J5<>"",TODAY()-J5,IF(E5<>"",TODAY()-E5,""))))))
A6: C-004 | B6: Robert | C6: Williams | D6: Database | E6: 46109 | F6: Sr. Analyst | G6: Analyst | H6: Secret | I6: S. Patel | J6: 46111 | K6: Pass | L6: 46114 | M6: T. Washington | N6: 4 | O6: Pass | P6: 46117 | Q6: 92000 | R6: Y | S6: 46118 | T6: Pending | U6: Pass | V6: 46126 | W6: Onboarding | X6: =IF(V6<>"",TODAY()-V6,IF(S6<>"",TODAY()-S6,IF(P6<>"",TODAY()-P6,IF(L6<>"",TODAY()-L6,IF(J6<>"",TODAY()-J6,IF(E6<>"",TODAY()-E6,"")))))) | Z6: Awaiting clearance
A7: C-005 | B7: Priya | C7: Sharma | D7: Job Board | E7: 46110 | F7: Data Entry Clerk | G7: Admin | H7: Public Trust | I7: J. Rivera | J7: 46112 | K7: Pass | L7: 46115 | M7: L. Chen | N7: 3.5 | O7: Pass | P7: 46118 | Q7: 55000 | R7: Y | S7: 46119 | T7: Clear | U7: Pass | V7: 46125 | W7: Deployed | X7: =IF(V7<>"",TODAY()-V7,IF(S7<>"",TODAY()-S7,IF(P7<>"",TODAY()-P7,IF(L7<>"",TODAY()-L7,IF(J7<>"",TODAY()-J7,IF(E7<>"",TODAY()-E7,""))))))
A8: C-006 | B8: David | C8: Thompson | D8: Internal | E8: 46111 | F8: QA Specialist | G8: Quality | H8: Public Trust | I8: S. Patel | J8: 46113 | K8: Pass | L8: 46116 | M8: M. Kim | N8: 4.3 | O8: Pass | P8: 46119 | Q8: 78000 | R8: Y | S8: 46120 | T8: Clear | U8: Pass | V8: 46126 | W8: Deployed | X8: =IF(V8<>"",TODAY()-V8,IF(S8<>"",TODAY()-S8,IF(P8<>"",TODAY()-P8,IF(L8<>"",TODAY()-L8,IF(J8<>"",TODAY()-J8,IF(E8<>"",TODAY()-E8,""))))))
A9: C-007 | B9: Sarah | C9: Brown | D9: Referral | E9: 46113 | F9: Case Analyst | G9: Analyst | H9: Public Trust | I9: J. Rivera | J9: 46115 | K9: Pass | L9: 46119 | M9: T. Washington | N9: 3.9 | O9: Pass | P9: 46122 | Q9: 72000 | R9: Y | S9: 46123 | T9: Pending | U9: Scheduled | V9: 46132 | W9: Onboarding | X9: =IF(V9<>"",TODAY()-V9,IF(S9<>"",TODAY()-S9,IF(P9<>"",TODAY()-P9,IF(L9<>"",TODAY()-L9,IF(J9<>"",TODAY()-J9,IF(E9<>"",TODAY()-E9,""))))))
A10: C-008 | B10: Michael | C10: Davis | D10: Job Board | E10: 46114 | F10: Security Analyst | G10: Security | H10: TS | I10: S. Patel | J10: 46116 | K10: Pass | L10: 46120 | M10: L. Chen | N10: 4.7 | O10: Pass | P10: 46123 | Q10: 98000 | R10: Y | S10: 46124 | T10: Submitted | U10: Pass | W10: Accepted | X10: =IF(V10<>"",TODAY()-V10,IF(S10<>"",TODAY()-S10,IF(P10<>"",TODAY()-P10,IF(L10<>"",TODAY()-L10,IF(J10<>"",TODAY()-J10,IF(E10<>"",TODAY()-E10,"")))))) | Z10: Clearance pending
A11: C-009 | B11: Jennifer | C11: Garcia | D11: Staffing Agency | E11: 46115 | F11: Program Support | G11: Admin | H11: Public Trust | I11: J. Rivera | J11: 46117 | K11: Pass | L11: 46121 | M11: M. Kim | N11: 3.6 | O11: Pass | P11: 46124 | Q11: 65000 | R11: N | W11: Withdrawn | X11: =IF(V11<>"",TODAY()-V11,IF(S11<>"",TODAY()-S11,IF(P11<>"",TODAY()-P11,IF(L11<>"",TODAY()-L11,IF(J11<>"",TODAY()-J11,IF(E11<>"",TODAY()-E11,"")))))) | Y11: Accepted competing offer
A12: C-010 | B12: Kevin | C12: Lee | D12: Database | E12: 46116 | F12: Network Engineer | G12: IT | H12: Secret | I12: S. Patel | J12: 46119 | K12: Pass | L12: 46122 | M12: T. Washington | N12: 4.1 | O12: Pass | P12: 46126 | Q12: 90000 | R12: Y | S12: 46127 | T12: Initiated | U12: Scheduled | W12: Accepted | X12: =IF(V12<>"",TODAY()-V12,IF(S12<>"",TODAY()-S12,IF(P12<>"",TODAY()-P12,IF(L12<>"",TODAY()-L12,IF(J12<>"",TODAY()-J12,IF(E12<>"",TODAY()-E12,""))))))
A13: C-011 | B13: Amanda | C13: Taylor | D13: Job Board | E13: 46117 | F13: Case Analyst | G13: Analyst | H13: Public Trust | I13: J. Rivera | J13: 46120 | K13: Pass | L13: 46123 | M13: L. Chen | N13: 4.4 | O13: Pass | W13: Interviewed | X13: =IF(V13<>"",TODAY()-V13,IF(S13<>"",TODAY()-S13,IF(P13<>"",TODAY()-P13,IF(L13<>"",TODAY()-L13,IF(J13<>"",TODAY()-J13,IF(E13<>"",TODAY()-E13,"")))))) | Z13: Strong candidate
A14: C-012 | B14: Carlos | C14: Rodriguez | D14: Referral | E14: 46118 | F14: Sr. Case Analyst | G14: Analyst | H14: Secret | I14: S. Patel | J14: 46121 | K14: Pass | L14: 46126 | M14: M. Kim | N14: 3.7 | O14: Maybe | W14: Interviewed | X14: =IF(V14<>"",TODAY()-V14,IF(S14<>"",TODAY()-S14,IF(P14<>"",TODAY()-P14,IF(L14<>"",TODAY()-L14,IF(J14<>"",TODAY()-J14,IF(E14<>"",TODAY()-E14,"")))))) | Z14: Needs second interview
A15: C-013 | B15: Lisa | C15: Anderson | D15: Staffing Agency | E15: 46119 | F15: Training Specialist | G15: Training | H15: Public Trust | I15: J. Rivera | J15: 46122 | K15: Pass | W15: Screened | X15: =IF(V15<>"",TODAY()-V15,IF(S15<>"",TODAY()-S15,IF(P15<>"",TODAY()-P15,IF(L15<>"",TODAY()-L15,IF(J15<>"",TODAY()-J15,IF(E15<>"",TODAY()-E15,""))))))
A16: C-014 | B16: Thomas | C16: Martinez | D16: Job Board | E16: 46120 | F16: Help Desk Tech | G16: IT | H16: Public Trust | I16: S. Patel | J16: 46123 | K16: Pass | W16: Screened | X16: =IF(V16<>"",TODAY()-V16,IF(S16<>"",TODAY()-S16,IF(P16<>"",TODAY()-P16,IF(L16<>"",TODAY()-L16,IF(J16<>"",TODAY()-J16,IF(E16<>"",TODAY()-E16,""))))))
A17: C-015 | B17: Rachel | C17: Wilson | D17: Database | E17: 46121 | F17: Case Analyst | G17: Analyst | H17: Public Trust | I17: J. Rivera | J17: 46124 | K17: Fail | W17: Withdrawn | X17: =IF(V17<>"",TODAY()-V17,IF(S17<>"",TODAY()-S17,IF(P17<>"",TODAY()-P17,IF(L17<>"",TODAY()-L17,IF(J17<>"",TODAY()-J17,IF(E17<>"",TODAY()-E17,"")))))) | Y17: Failed phone screen
A18: C-016 | B18: Brian | C18: Harris | D18: Internal | E18: 46122 | F18: Supervisor | G18: Management | H18: Secret | I18: S. Patel | J18: 46125 | K18: Pass | L18: 46129 | M18: T. Washington | N18: 4.6 | W18: Interviewed | X18: =IF(V18<>"",TODAY()-V18,IF(S18<>"",TODAY()-S18,IF(P18<>"",TODAY()-P18,IF(L18<>"",TODAY()-L18,IF(J18<>"",TODAY()-J18,IF(E18<>"",TODAY()-E18,""))))))
A19: C-017 | B19: Nicole | C19: Clark | D19: Job Board | E19: 46123 | F19: Data Entry Clerk | G19: Admin | H19: Public Trust | I19: J. Rivera | J19: 46126 | K19: Pass | W19: Screened | X19: =IF(V19<>"",TODAY()-V19,IF(S19<>"",TODAY()-S19,IF(P19<>"",TODAY()-P19,IF(L19<>"",TODAY()-L19,IF(J19<>"",TODAY()-J19,IF(E19<>"",TODAY()-E19,""))))))
A20: C-018 | B20: Anthony | C20: Lewis | D20: Staffing Agency | E20: 46125 | F20: Case Analyst | G20: Analyst | H20: Public Trust | I20: S. Patel | J20: 46128 | K20: Pass | W20: Screened | X20: =IF(V20<>"",TODAY()-V20,IF(S20<>"",TODAY()-S20,IF(P20<>"",TODAY()-P20,IF(L20<>"",TODAY()-L20,IF(J20<>"",TODAY()-J20,IF(E20<>"",TODAY()-E20,""))))))
A21: C-019 | B21: Michelle | C21: Walker | D21: Referral | E21: 46127 | F21: Program Analyst | G21: Analyst | H21: Secret | I21: J. Rivera | W21: Sourced | X21: =IF(V21<>"",TODAY()-V21,IF(S21<>"",TODAY()-S21,IF(P21<>"",TODAY()-P21,IF(L21<>"",TODAY()-L21,IF(J21<>"",TODAY()-J21,IF(E21<>"",TODAY()-E21,""))))))
A22: C-020 | B22: Daniel | C22: Hall | D22: Database | E22: 46129 | F22: Case Analyst | G22: Analyst | H22: Public Trust | I22: S. Patel | W22: Sourced | X22: =IF(V22<>"",TODAY()-V22,IF(S22<>"",TODAY()-S22,IF(P22<>"",TODAY()-P22,IF(L22<>"",TODAY()-L22,IF(J22<>"",TODAY()-J22,IF(E22<>"",TODAY()-E22,""))))))

Sheet Interview Scorecard
A1: INTERVIEW SCORECARD
A2: Interview ID | B2: Date | C2: Candidate ID | D2: Candidate Name | E2: Position | F2: Interviewer | G2: Communication | H2: Technical Knowledge | I2: Problem Solving | J2: Experience Relevance | K2: Cultural Fit | L2: Remote Work Readiness | M2: Weighted Total | N2: Recommendation | O2: Strengths | P2: Concerns | Q2: Notes
A3: INT-001 | B3: 46111 | C3: C-001 | D3: Maria Santos | E3: Case Analyst | F3: T. Washington | G3: 4 | H3: 4 | I3: 4 | J3: 5 | K3: 4 | L3: 5 | M3: =ROUND((G3*0.15+H3*0.2+I3*0.2+J3*0.15+K3*0.15+L3*0.15)*20,1) | N3: Strong Hire | O3: Excellent remote experience, strong communicator | P3: None noted
A4: INT-002 | B4: 46112 | C4: C-002 | D4: James Mitchell | E4: Program Support | F4: L. Chen | G4: 4 | H4: 3 | I4: 3 | J4: 4 | K4: 4 | L4: 4 | M4: =ROUND((G4*0.15+H4*0.2+I4*0.2+J4*0.15+K4*0.15+L4*0.15)*20,1) | N4: Hire | O4: Good organizational skills | P4: Limited govt experience
A5: INT-003 | B5: 46113 | C5: C-003 | D5: Aisha Johnson | E5: IT Support Spec | F5: M. Kim | G5: 5 | H5: 5 | I5: 4 | J5: 5 | K5: 4 | L5: 4 | M5: =ROUND((G5*0.15+H5*0.2+I5*0.2+J5*0.15+K5*0.15+L5*0.15)*20,1) | N5: Strong Hire | O5: Deep technical knowledge, certs current | P5: Relocating soon
A6: INT-004 | B6: 46114 | C6: C-004 | D6: Robert Williams | E6: Sr. Analyst | F6: T. Washington | G6: 4 | H6: 4 | I6: 4 | J6: 4 | K6: 4 | L6: 3 | M6: =ROUND((G6*0.15+H6*0.2+I6*0.2+J6*0.15+K6*0.15+L6*0.15)*20,1) | N6: Hire | O6: Solid analytical background | P6: Remote readiness needs setup
A7: INT-005 | B7: 46115 | C7: C-005 | D7: Priya Sharma | E7: Data Entry Clerk | F7: L. Chen | G7: 3 | H7: 3 | I7: 3 | J7: 4 | K7: 4 | L7: 4 | M7: =ROUND((G7*0.15+H7*0.2+I7*0.2+J7*0.15+K7*0.15+L7*0.15)*20,1) | N7: Hire | O7: Accurate and detail-oriented | P7: Speed below benchmark
A8: INT-006 | B8: 46116 | C8: C-006 | D8: David Thompson | E8: QA Specialist | F8: M. Kim | G8: 4 | H8: 4 | I8: 5 | J8: 4 | K8: 5 | L8: 4 | M8: =ROUND((G8*0.15+H8*0.2+I8*0.2+J8*0.15+K8*0.15+L8*0.15)*20,1) | N8: Strong Hire | O8: QA methodology expert | P8: None noted
A9: INT-007 | B9: 46119 | C9: C-007 | D9: Sarah Brown | E9: Case Analyst | F9: T. Washington | G9: 4 | H9: 3 | I9: 4 | J9: 4 | K9: 4 | L9: 4 | M9: =ROUND((G9*0.15+H9*0.2+I9*0.2+J9*0.15+K9*0.15+L9*0.15)*20,1) | N9: Hire | O9: Eager learner, positive attitude | P9: Needs training on systems
A10: INT-008 | B10: 46120 | C10: C-008 | D10: Michael Davis | E10: Security Analyst | F10: L. Chen | G10: 5 | H10: 5 | I10: 5 | J10: 5 | K10: 4 | L10: 4 | M10: =ROUND((G10*0.15+H10*0.2+I10*0.2+J10*0.15+K10*0.15+L10*0.15)*20,1) | N10: Strong Hire | O10: Exceptional security knowledge | P10: TS clearance timeline
A11: INT-009 | B11: 46121 | C11: C-009 | D11: Jennifer Garcia | E11: Program Support | F11: M. Kim | G11: 3 | H11: 3 | I11: 3 | J11: 3 | K11: 4 | L11: 4 | M11: =ROUND((G11*0.15+H11*0.2+I11*0.2+J11*0.15+K11*0.15+L11*0.15)*20,1) | N11: Maybe | O11: Pleasant demeanor | P11: Lacks relevant experience | Q11: Withdrew after interview
A12: INT-010 | B12: 46122 | C12: C-010 | D12: Kevin Lee | E12: Network Engineer | F12: T. Washington | G12: 4 | H12: 5 | I12: 4 | J12: 4 | K12: 3 | L12: 4 | M12: =ROUND((G12*0.15+H12*0.2+I12*0.2+J12*0.15+K12*0.15+L12*0.15)*20,1) | N12: Hire | O12: Strong networking skills | P12: Limited remote tool experience
A13: INT-011 | B13: 46123 | C13: C-011 | D13: Amanda Taylor | E13: Case Analyst | F13: L. Chen | G13: 5 | H13: 4 | I13: 4 | J13: 5 | K13: 5 | L13: 4 | M13: =ROUND((G13*0.15+H13*0.2+I13*0.2+J13*0.15+K13*0.15+L13*0.15)*20,1) | N13: Strong Hire | O13: Outstanding communication | P13: None noted
A14: INT-012 | B14: 46126 | C14: C-012 | D14: Carlos Rodriguez | E14: Sr. Case Analyst | F14: M. Kim | G14: 3 | H14: 4 | I14: 3 | J14: 4 | K14: 3 | L14: 4 | M14: =ROUND((G14*0.15+H14*0.2+I14*0.2+J14*0.15+K14*0.15+L14*0.15)*20,1) | N14: Maybe | O14: Good technical skills | P14: Communication needs improvement | Q14: Second interview recommended
A15: INT-013 | B15: 46129 | C15: C-016 | D15: Brian Harris | E15: Supervisor | F15: T. Washington | G15: 5 | H15: 4 | I15: 4 | J15: 5 | K15: 5 | L15: 4 | M15: =ROUND((G15*0.15+H15*0.2+I15*0.2+J15*0.15+K15*0.15+L15*0.15)*20,1) | N15: Strong Hire | O15: Leadership experience, mentoring skills | P15: Salary expectations high
A16: INT-014 | B16: 46120 | C16: C-001 | D16: Maria Santos | E16: Case Analyst | F16: L. Chen | G16: 4 | H16: 4 | I16: 5 | J16: 5 | K16: 4 | L16: 5 | M16: =ROUND((G16*0.15+H16*0.2+I16*0.2+J16*0.15+K16*0.15+L16*0.15)*20,1) | N16: Strong Hire | O16: Confirmed strong fit | P16: None | Q16: Second opinion interview
A17: INT-015 | B17: 46122 | C17: C-004 | D17: Robert Williams | E17: Sr. Analyst | F17: M. Kim | G17: 4 | H17: 4 | I17: 3 | J17: 4 | K17: 4 | L17: 4 | M17: =ROUND((G17*0.15+H17*0.2+I17*0.2+J17*0.15+K17*0.15+L17*0.15)*20,1) | N17: Hire | O17: Analytical depth | P17: Problem solving average

Sheet E-QIP Tracker
A1: E-QIP / SECURITY CLEARANCE TRACKER
A2: Employee ID | B2: Last Name | C2: First Name | D2: Position | E2: Clearance Level Required | F2: eQIP Account Created | G2: eQIP Acct Date | H2: OF-306 Submitted | I2: OF-306 Date | J2: eQIP Initiated Date | K2: eQIP Submitted Date | L2: Agency Received Date | M2: Fingerprints Scheduled | N2: Fingerprints Completed | O2: Interim Requested | P2: Interim Decision | Q2: Interim Date | R2: Investigation Opened | S2: Investigation Type | T2: Adjudication Date | U2: Final Decision | V2: Final Clearance Date | W2: Expiration Date | X2: Continuous Eval | Y2: Status | Z2: Days in Stage | AA2: Notes
A3: E-001 | B3: Santos | C3: Maria | D3: Case Analyst | E3: Public Trust | F3: Y | G3: 46109 | H3: Y | I3: 46110 | J3: 46111 | K3: 46113 | L3: 46114 | M3: 46115 | N3: 46115 | O3: N | R3: 46117 | S3: T1 | T3: 46124 | U3: Favorable | V3: 46124 | W3: 47950 | X3: Y | Y3: Complete | Z3: 0
A4: E-002 | B4: Mitchell | C4: James | D4: Program Support | E4: Public Trust | F4: Y | G4: 46110 | H4: Y | I4: 46111 | J4: 46112 | K4: 46114 | L4: 46115 | M4: 46116 | N4: 46116 | O4: N | R4: 46118 | S4: T1 | T4: 46126 | U4: Favorable | V4: 46126 | W4: 47952 | X4: Y | Y4: Complete | Z4: 0
A5: E-003 | B5: Johnson | C5: Aisha | D5: IT Support Spec | E5: Secret | F5: Y | G5: 46111 | H5: Y | I5: 46112 | J5: 46113 | K5: 46115 | L5: 46116 | M5: 46117 | N5: 46117 | O5: Y | P5: Granted | Q5: 46119 | R5: 46120 | S5: T3 | X5: N | Y5: Investigation | Z5: 12 | AA5: Interim granted
A6: E-004 | B6: Williams | C6: Robert | D6: Sr. Analyst | E6: Secret | F6: Y | G6: 46113 | H6: Y | I6: 46114 | J6: 46115 | K6: 46117 | L6: 46118 | M6: 46119 | N6: 46119 | O6: Y | P6: Pending | S6: T3 | X6: N | Y6: Interim Pending | Z6: 14 | AA6: Awaiting interim decision
A7: E-005 | B7: Sharma | C7: Priya | D7: Data Entry Clerk | E7: Public Trust | F7: Y | G7: 46114 | H7: Y | I7: 46115 | J7: 46116 | K7: 46118 | L7: 46119 | M7: 46120 | N7: 46120 | O7: N | R7: 46121 | S7: T1 | T7: 46128 | U7: Favorable | V7: 46128 | W7: 47954 | X7: Y | Y7: Complete | Z7: 0
A8: E-006 | B8: Thompson | C8: David | D8: QA Specialist | E8: Public Trust | F8: Y | G8: 46115 | H8: Y | I8: 46116 | J8: 46117 | K8: 46119 | L8: 46120 | M8: 46121 | N8: 46121 | O8: N | R8: 46122 | S8: T1 | T8: 46130 | U8: Favorable | V8: 46130 | W8: 47956 | X8: Y | Y8: Complete | Z8: 0
A9: E-007 | B9: Brown | C9: Sarah | D9: Case Analyst | E9: Public Trust | F9: Y | G9: 46117 | H9: Y | I9: 46118 | J9: 46119 | K9: 46121 | L9: 46122 | O9: N | S9: T1 | X9: N | Y9: Submitted | Z9: 10
A10: E-008 | B10: Davis | C10: Michael | D10: Security Analyst | E10: TS | F10: Y | G10: 46118 | H10: Y | I10: 46119 | J10: 46120 | K10: 46122 | M10: 46124 | O10: Y | P10: Pending | S10: T5 | X10: N | Y10: eQIP Submitted | Z10: 10 | AA10: TS timeline ~6-12 months
A11: E-009 | B11: Lee | C11: Kevin | D11: Network Engineer | E11: Secret | F11: Y | G11: 46120 | H11: Y | I11: 46121 | J11: 46122 | O11: N | S11: T3 | X11: N | Y11: eQIP Initiated | Z11: 10
A12: E-010 | B12: Taylor | C12: Amanda | D12: Case Analyst | E12: Public Trust | F12: Y | G12: 46122 | H12: Y | I12: 46123 | J12: 46124 | O12: N | S12: T1 | X12: N | Y12: OF-306 Submitted | Z12: 9
A13: E-011 | B13: Harris | C13: Brian | D13: Supervisor | E13: Secret | F13: Y | G13: 46124 | H13: N | O13: N | S13: T3 | X13: N | Y13: Account Created | Z13: 8 | AA13: Awaiting OF-306
A14: E-012 | B14: Rodriguez | C14: Carlos | D14: Sr. Case Analyst | E14: Secret | F14: N | H14: N | O14: N | S14: T3 | X14: N | Y14: Not Started | Z14: 6 | AA14: Pending hire decision
A15: E-013 | B15: Clark | C15: Nicole | D15: Data Entry Clerk | E15: Public Trust | F15: N | H15: N | O15: N | S15: T1 | X15: N | Y15: Not Started | Z15: 0 | AA15: Pending screening
A16: E-014 | B16: Lewis | C16: Anthony | D16: Case Analyst | E16: Public Trust | F16: N | H16: N | O16: N | S16: T1 | X16: N | Y16: Not Started | Z16: 0 | AA16: Pending screening
A17: E-015 | B17: Walker | C17: Michelle | D17: Program Analyst | E17: Secret | F17: N | H17: N | O17: N | S17: T3 | X17: N | Y17: Not Started | Z17: 0 | AA17: Not yet sourced

Sheet Employee Roster
A1: EMPLOYEE ROSTER — Master List
A2: Employee ID | B2: Last Name | C2: First Name | D2: Email | E2: Phone | F2: Position Title | G2: Labor Category | H2: Contract | I2: Supervisor | J2: Team | K2: Hire Date | L2: Start Date | M2: Status | N2: Clearance Level | O2: Clearance Status | P2: Equip Shipped | Q2: Equip Delivered | R2: Equip Verified | S2: Workspace Attest | T2: VPN Active | U2: Remote Readiness | V2: Training Status | W2: Training Complete Date | X2: Nesting Start | Y2: Nesting End | Z2: OJT Complete | AA2: Current QA Score | AB2: QA Trend | AC2: 30-Day Check-in | AD2: 60-Day Check-in | AE2: 90-Day Check-in | AF2: Attrition Risk | AG2: Separation Date | AH2: Separation Reason | AI2: Notes
A3: E-001 | B3: Santos | C3: Maria | D3: m.santos@contractor.gov | E3: 504-555-0101 | F3: Case Analyst | G3: Analyst | H3: GS-SURGE-2026 | I3: T. Washington | J3: Team Alpha | K3: 46115 | L3: 46121 | M3: Deployed | N3: Public Trust | O3: Active | P3: 46117 | Q3: 46119 | R3: Y | S3: Y | T3: Y | U3: Ready | V3: Complete | W3: 46124 | X3: 46125 | Y3: 46129 | Z3: Y | AA3: 88 | AB3: Improving | AC3: Complete | AD3: Pending | AF3: Low | AI3: Top performer
A4: E-002 | B4: Mitchell | C4: James | D4: j.mitchell@contractor.gov | E4: 504-555-0102 | F4: Program Support | G4: Admin | H4: GS-SURGE-2026 | I4: L. Chen | J4: Team Beta | K4: 46116 | L4: 46122 | M4: Deployed | N4: Public Trust | O4: Active | P4: 46118 | Q4: 46120 | R4: Y | S4: Y | T4: Y | U4: Ready | V4: Complete | W4: 46125 | X4: 46126 | Y4: 46130 | Z4: Y | AA4: 82 | AB4: Stable | AC4: Complete | AD4: Pending | AF4: Low
A5: E-003 | B5: Johnson | C5: Aisha | D5: a.johnson@contractor.gov | E5: 504-555-0103 | F5: IT Support Spec | G5: IT | H5: GS-SURGE-2026 | I5: M. Kim | J5: IT Support | K5: 46117 | L5: 46123 | M5: Deployed | N5: Secret | O5: Interim | P5: 46119 | Q5: 46121 | R5: Y | S5: Y | T5: Y | U5: Ready | V5: Complete | W5: 46126 | X5: 46127 | Y5: 46131 | Z5: Y | AA5: 91 | AB5: Improving | AC5: Complete | AD5: Pending | AF5: Low
A6: E-004 | B6: Williams | C6: Robert | D6: r.williams@contractor.gov | E6: 504-555-0104 | F6: Sr. Analyst | G6: Analyst | H6: GS-SURGE-2026 | I6: T. Washington | J6: Team Alpha | K6: 46118 | L6: 46126 | M6: Training | N6: Secret | O6: Pending | P6: 46122 | Q6: 46124 | R6: Y | S6: Y | T6: Y | U6: Ready | V6: In Progress | Z6: N | AC6: Pending | AF6: Medium | AI6: Clearance delay
A7: E-005 | B7: Sharma | C7: Priya | D7: p.sharma@contractor.gov | E7: 504-555-0105 | F7: Data Entry Clerk | G7: Admin | H7: GS-SURGE-2026 | I7: L. Chen | J7: Team Beta | K7: 46119 | L7: 46125 | M7: Deployed | N7: Public Trust | O7: Active | P7: 46121 | Q7: 46123 | R7: Y | S7: Y | T7: Y | U7: Ready | V7: Complete | W7: 46128 | X7: 46129 | Y7: 46132 | Z7: Y | AA7: 79 | AB7: Declining | AC7: Complete | AF7: Medium | AI7: QA trending down
A8: E-006 | B8: Thompson | C8: David | D8: d.thompson@contractor.gov | E8: 504-555-0106 | F8: QA Specialist | G8: Quality | H8: GS-SURGE-2026 | I8: M. Kim | J8: Quality | K8: 46120 | L8: 46126 | M8: Deployed | N8: Public Trust | O8: Active | P8: 46122 | Q8: 46124 | R8: Y | S8: Y | T8: Y | U8: Ready | V8: Complete | W8: 46129 | X8: 46130 | Y8: 46132 | Z8: Y | AA8: 94 | AB8: Stable | AC8: Complete | AF8: Low
A9: E-007 | B9: Brown | C9: Sarah | D9: s.brown@contractor.gov | E9: 504-555-0107 | F9: Case Analyst | G9: Analyst | H9: GS-SURGE-2026 | I9: T. Washington | J9: Team Alpha | K9: 46123 | L9: 46132 | M9: Training | N9: Public Trust | O9: Pending | P9: 46127 | Q9: 46129 | R9: Y | S9: Y | T9: Y | U9: Ready | V9: In Progress | Z9: N | AC9: Pending | AF9: Low
A10: E-008 | B10: Davis | C10: Michael | D10: m.davis@contractor.gov | E10: 504-555-0108 | F10: Security Analyst | G10: Security | H10: GS-SURGE-2026 | I10: M. Kim | J10: Security | K10: 46124 | M10: Onboarding | N10: TS | O10: Pending | P10: 46128 | Q10: 46130 | R10: Y | S10: Y | T10: N | U10: Pending | V10: Not Started | Z10: N | AF10: Medium | AI10: Awaiting TS clearance
A11: E-009 | B11: Lee | C11: Kevin | D11: k.lee@contractor.gov | E11: 504-555-0109 | F11: Network Engineer | G11: IT | H11: GS-SURGE-2026 | I11: M. Kim | J11: IT Support | K11: 46127 | M11: Onboarding | N11: Secret | O11: Pending | P11: 46129 | R11: N | S11: N | T11: N | U11: Blocked | V11: Not Started | Z11: N | AF11: Medium | AI11: Equipment in transit
A12: E-010 | B12: Taylor | C12: Amanda | D12: a.taylor@contractor.gov | E12: 504-555-0110 | F12: Case Analyst | G12: Analyst | H12: GS-SURGE-2026 | I12: T. Washington | J12: Team Alpha | K12: 46130 | M12: Onboarding | N12: Public Trust | O12: Pending | R12: N | S12: N | T12: N | U12: Blocked | V12: Not Started | Z12: N | AF12: Low | AI12: Pending offer accept
A13: E-011 | B13: Parker | C13: Jason | D13: j.parker@contractor.gov | E13: 504-555-0111 | F13: Case Analyst | G13: Analyst | H13: GS-SURGE-2026 | I13: L. Chen | J13: Team Beta | K13: 46115 | L13: 46121 | M13: Deployed | N13: Public Trust | O13: Active | P13: 46117 | Q13: 46119 | R13: Y | S13: Y | T13: Y | U13: Ready | V13: Complete | W13: 46124 | X13: 46125 | Y13: 46129 | Z13: Y | AA13: 85 | AB13: Stable | AC13: Complete | AD13: Pending | AF13: Low
A14: E-012 | B14: Rivera | C14: Carmen | D14: c.rivera@contractor.gov | E14: 504-555-0112 | F14: Case Analyst | G14: Analyst | H14: GS-SURGE-2026 | I14: L. Chen | J14: Team Beta | K14: 46116 | L14: 46122 | M14: Deployed | N14: Public Trust | O14: Active | P14: 46118 | Q14: 46120 | R14: Y | S14: Y | T14: Y | U14: Ready | V14: Complete | W14: 46125 | X14: 46126 | Y14: 46130 | Z14: Y | AA14: 76 | AB14: Declining | AC14: Complete | AD14: Pending | AF14: High | AI14: Performance concerns
A15: E-013 | B15: Nguyen | C15: Tran | D15: t.nguyen@contractor.gov | E15: 504-555-0113 | F15: Program Support | G15: Admin | H15: GS-SURGE-2026 | I15: T. Washington | J15: Team Alpha | K15: 46117 | L15: 46123 | M15: Deployed | N15: Public Trust | O15: Active | P15: 46119 | Q15: 46121 | R15: Y | S15: Y | T15: Y | U15: Ready | V15: Complete | W15: 46126 | X15: 46127 | Y15: 46131 | Z15: Y | AA15: 87 | AB15: Improving | AC15: Complete | AD15: Pending | AF15: Low
A16: E-014 | B16: Foster | C16: Derek | D16: d.foster@contractor.gov | E16: 504-555-0114 | F16: Case Analyst | G16: Analyst | H16: GS-SURGE-2026 | I16: L. Chen | J16: Team Beta | K16: 46118 | L16: 46125 | M16: Nesting | N16: Public Trust | O16: Active | P16: 46121 | Q16: 46123 | R16: Y | S16: Y | T16: Y | U16: Ready | V16: Complete | W16: 46128 | X16: 46129 | Z16: N | AA16: 81 | AB16: Stable | AC16: Pending | AF16: Low
A17: E-015 | B17: Kim | C17: Susan | D17: s.kim@contractor.gov | E17: 504-555-0115 | F17: Training Specialist | G17: Training | H17: GS-SURGE-2026 | I17: M. Kim | J17: Training | K17: 46119 | L17: 46125 | M17: Deployed | N17: Public Trust | O17: Active | P17: 46121 | Q17: 46123 | R17: Y | S17: Y | T17: Y | U17: Ready | V17: Complete | W17: 46126 | Z17: Y | AA17: 90 | AB17: Stable | AC17: Complete | AF17: Low
A18: E-016 | B18: Washington | C18: Tyler | D18: t.washington@contractor.gov | E18: 504-555-0116 | F18: Supervisor | G18: Management | H18: GS-SURGE-2026 | I18: Program Mgr | J18: Management | K18: 46096 | L18: 46101 | M18: Deployed | N18: Secret | O18: Active | P18: 46098 | Q18: 46099 | R18: Y | S18: Y | T18: Y | U18: Ready | V18: Complete | W18: 46103 | Z18: Y | AA18: 95 | AB18: Stable | AC18: Complete | AD18: Complete | AE18: Pending | AF18: Low
A19: E-017 | B19: Chen | C19: Lisa | D19: l.chen@contractor.gov | E19: 504-555-0117 | F19: Supervisor | G19: Management | H19: GS-SURGE-2026 | I19: Program Mgr | J19: Management | K19: 46096 | L19: 46101 | M19: Deployed | N19: Secret | O19: Active | P19: 46098 | Q19: 46099 | R19: Y | S19: Y | T19: Y | U19: Ready | V19: Complete | W19: 46103 | Z19: Y | AA19: 93 | AB19: Stable | AC19: Complete | AD19: Complete | AE19: Pending | AF19: Low
A20: E-018 | B20: Patel | C20: Sanjay | D20: s.patel@contractor.gov | E20: 504-555-0118 | F20: Recruiting Lead | G20: Recruiting | H20: GS-SURGE-2026 | I20: Program Mgr | J20: Recruiting | K20: 46091 | L20: 46096 | M20: Deployed | N20: Public Trust | O20: Active | P20: 46093 | Q20: 46094 | R20: Y | S20: Y | T20: Y | U20: Ready | V20: Complete | W20: 46097 | Z20: Y | AC20: Complete | AD20: Complete | AE20: Complete | AF20: Low
A21: E-019 | B21: Martinez | C21: Alex | D21: a.martinez@contractor.gov | E21: 504-555-0119 | F21: Case Analyst | G21: Analyst | H21: GS-SURGE-2026 | I21: T. Washington | J21: Team Alpha | K21: 46115 | L21: 46121 | M21: Separated | N21: Public Trust | O21: Active | P21: 46117 | Q21: 46119 | R21: Y | S21: Y | T21: Y | U21: Ready | V21: Complete | W21: 46124 | X21: 46125 | Y21: 46129 | Z21: Y | AA21: 72 | AB21: Declining | AC21: Complete | AG21: 46130 | AH21: Voluntary - personal reasons | AI21: Returned equipment
A22: E-020 | B22: Brooks | C22: Dana | D22: d.brooks@contractor.gov | E22: 504-555-0120 | F22: Help Desk Tech | G22: IT | H22: GS-SURGE-2026 | I22: M. Kim | J22: IT Support | K22: 46122 | L22: 46128 | M22: Training | N22: Public Trust | O22: Active | P22: 46124 | Q22: 46126 | R22: Y | S22: Y | T22: Y | U22: Ready | V22: In Progress | Z22: N | AC22: Pending | AF22: Low

Sheet Staffing Dashboard
A1: STAFFING DASHBOARD — Workforce Operations View
A3: HEADCOUNT BY STATUS | D3: HEADCOUNT BY TEAM | G3: HEADCOUNT BY SUPERVISOR | J3: RAMP PLAN vs ACTUAL
A4: Deployed | B4: =COUNTIF('Employee Roster'!M3:M22,A4) | D4: Team Alpha | E4: =COUNTIF('Employee Roster'!J3:J22,D4) | G4: T. Washington | H4: =COUNTIF('Employee Roster'!I3:I22,G4) | J4: Period | K4: Actual | L4: Target
A5: Training | B5: =COUNTIF('Employee Roster'!M3:M22,A5) | D5: Team Beta | E5: =COUNTIF('Employee Roster'!J3:J22,D5) | G5: L. Chen | H5: =COUNTIF('Employee Roster'!I3:I22,G5) | J5: Pre-Surge | K5: 3 | L5: 3
A6: Nesting | B6: =COUNTIF('Employee Roster'!M3:M22,A6) | D6: IT Support | E6: =COUNTIF('Employee Roster'!J3:J22,D6) | G6: M. Kim | H6: =COUNTIF('Employee Roster'!I3:I22,G6) | J6: Week 1 | K6: 10 | L6: 12
A7: Onboarding | B7: =COUNTIF('Employee Roster'!M3:M22,A7) | D7: Quality | E7: =COUNTIF('Employee Roster'!J3:J22,D7) | G7: Program Mgr | H7: =COUNTIF('Employee Roster'!I3:I22,G7) | J7: Week 2 | K7: 18 | L7: 20
A8: Separated | B8: =COUNTIF('Employee Roster'!M3:M22,A8) | D8: Security | E8: =COUNTIF('Employee Roster'!J3:J22,D8) | J8: Week 3 | K8: 25 | L8: 28
A9: TOTAL ACTIVE | B9: =SUM(B4:B7) | D9: Training | E9: =COUNTIF('Employee Roster'!J3:J22,D9) | J9: Week 4 (Plan) | K9: 32 | L9: 35
D10: Management | E10: =COUNTIF('Employee Roster'!J3:J22,D10)
D11: Recruiting | E11: =COUNTIF('Employee Roster'!J3:J22,D11)
A13: EQUIPMENT TRACKING SUMMARY | E13: REMOTE READINESS | H13: TRAINING PIPELINE
A14: Metric | B14: Count | C14: Rate | E14: Ready | F14: =COUNTIF('Employee Roster'!U3:U22,E14) | H14: Complete | I14: =COUNTIF('Employee Roster'!V3:V22,H14)
A15: Total Employees | B15: =COUNTA('Employee Roster'!A3:A22) | E15: Pending | F15: =COUNTIF('Employee Roster'!U3:U22,E15) | H15: In Progress | I15: =COUNTIF('Employee Roster'!V3:V22,H15)
A16: Equipment Shipped | B16: =COUNTIF('Employee Roster'!P3:P22,"<>") | C16: =IF(B15=0,0,B16/B15) | E16: Blocked | F16: =COUNTIF('Employee Roster'!U3:U22,E16) | H16: Not Started | I16: =COUNTIF('Employee Roster'!V3:V22,H16)
A17: Equipment Delivered | B17: =COUNTIF('Employee Roster'!Q3:Q22,"<>") | C17: =IF(B15=0,0,B17/B15)
A18: Equipment Verified | B18: =COUNTIF('Employee Roster'!R3:R22,"Y") | C18: =IF(B15=0,0,B18/B15)
A19: Workspace Attested | B19: =COUNTIF('Employee Roster'!S3:S22,"Y") | C19: =IF(B15=0,0,B19/B15)
A20: VPN Active | B20: =COUNTIF('Employee Roster'!T3:T22,"Y") | C20: =IF(B15=0,0,B20/B15)

Sheet Retention Tracker
A1: RETENTION TRACKER
A2: Employee ID | B2: Name | C2: Cohort | D2: Hire Date | E2: 30-Day Check-in Date | F2: 30-Day Status | G2: 30-Day Score | H2: 60-Day Check-in Date | I2: 60-Day Status | J2: 60-Day Score | K2: 90-Day Check-in Date | L2: 90-Day Status | M2: 90-Day Score | N2: Engagement Score | O2: Attrition Risk | P2: Separation Date | Q2: Separation Reason | R2: Tenure Days | S2: Notes
A3: E-001 | B3: Maria Santos | C3: Cohort 1 | D3: 46115 | E3: 46145 | F3: Complete | G3: 4.2 | I3: Pending | N3: 4 | O3: Low | R3: =IF(P3<>"",P3-D3,TODAY()-D3)
A4: E-002 | B4: James Mitchell | C4: Cohort 1 | D4: 46116 | E4: 46146 | F4: Complete | G4: 3.8 | I4: Pending | N4: 3.5 | O4: Low | R4: =IF(P4<>"",P4-D4,TODAY()-D4)
A5: E-003 | B5: Aisha Johnson | C5: Cohort 1 | D5: 46117 | E5: 46147 | F5: Complete | G5: 4.5 | I5: Pending | N5: 4.3 | O5: Low | R5: =IF(P5<>"",P5-D5,TODAY()-D5)
A6: E-004 | B6: Robert Williams | C6: Cohort 1 | D6: 46118 | E6: 46148 | F6: Pending | N6: 3.2 | O6: Medium | R6: =IF(P6<>"",P6-D6,TODAY()-D6) | S6: Clearance causing frustration
A7: E-005 | B7: Priya Sharma | C7: Cohort 1 | D7: 46119 | E7: 46149 | F7: Pending | N7: 3 | O7: Medium | R7: =IF(P7<>"",P7-D7,TODAY()-D7) | S7: QA scores declining
A8: E-006 | B8: David Thompson | C8: Cohort 1 | D8: 46120 | E8: 46150 | F8: Pending | N8: 4.5 | O8: Low | R8: =IF(P8<>"",P8-D8,TODAY()-D8)
A9: E-007 | B9: Sarah Brown | C9: Cohort 1 | D9: 46123 | E9: 46153 | F9: Pending | N9: 3.8 | O9: Low | R9: =IF(P9<>"",P9-D9,TODAY()-D9)
A10: E-011 | B10: Jason Parker | C10: Cohort 1 | D10: 46115 | E10: 46145 | F10: Complete | G10: 4 | I10: Pending | N10: 3.9 | O10: Low | R10: =IF(P10<>"",P10-D10,TODAY()-D10)
A11: E-012 | B11: Carmen Rivera | C11: Cohort 1 | D11: 46116 | E11: 46146 | F11: Complete | G11: 2.8 | I11: Pending | N11: 2.5 | O11: High | R11: =IF(P11<>"",P11-D11,TODAY()-D11) | S11: Expressed dissatisfaction
A12: E-013 | B12: Tran Nguyen | C12: Cohort 1 | D12: 46117 | E12: 46147 | F12: Complete | G12: 4.1 | I12: Pending | N12: 4 | O12: Low | R12: =IF(P12<>"",P12-D12,TODAY()-D12)
A13: E-014 | B13: Derek Foster | C13: Cohort 1 | D13: 46118 | E13: 46148 | F13: Pending | N13: 3.6 | O13: Low | R13: =IF(P13<>"",P13-D13,TODAY()-D13)
A14: E-015 | B14: Susan Kim | C14: Cohort 1 | D14: 46119 | E14: 46149 | F14: Pending | N14: 4.2 | O14: Low | R14: =IF(P14<>"",P14-D14,TODAY()-D14)
A15: E-016 | B15: Tyler Washington | C15: Pre-Surge | D15: 46096 | E15: 46126 | F15: Complete | G15: 4.8 | H15: 46156 | I15: Complete | J15: 4.7 | L15: Pending | N15: 4.9 | O15: Low | R15: =IF(P15<>"",P15-D15,TODAY()-D15)
A16: E-017 | B16: Lisa Chen | C16: Pre-Surge | D16: 46096 | E16: 46126 | F16: Complete | G16: 4.6 | H16: 46156 | I16: Complete | J16: 4.5 | L16: Pending | N16: 4.7 | O16: Low | R16: =IF(P16<>"",P16-D16,TODAY()-D16)
A17: E-018 | B17: Sanjay Patel | C17: Pre-Surge | D17: 46091 | E17: 46121 | F17: Complete | G17: 4.3 | H17: 46151 | I17: Complete | J17: 4.4 | K17: 46181 | L17: Pending | N17: 4.5 | O17: Low | R17: =IF(P17<>"",P17-D17,TODAY()-D17)
A18: E-019 | B18: Alex Martinez | C18: Cohort 1 | D18: 46115 | E18: 46145 | F18: Complete | G18: 2.5 | N18: 2 | O18: High | P18: 46130 | Q18: Voluntary - personal reasons | R18: =IF(P18<>"",P18-D18,TODAY()-D18) | S18: Left during nesting phase
A19: E-020 | B19: Dana Brooks | C19: Cohort 2 | D19: 46122 | E19: 46152 | F19: Pending | N19: 3.7 | O19: Low | R19: =IF(P19<>"",P19-D19,TODAY()-D19)
A20: E-008 | B20: Michael Davis | C20: Cohort 2 | D20: 46124 | E20: 46154 | F20: Pending | N20: 3.4 | O20: Medium | R20: =IF(P20<>"",P20-D20,TODAY()-D20) | S20: Clearance uncertainty
A21: E-009 | B21: Kevin Lee | C21: Cohort 2 | D21: 46127 | E21: 46157 | F21: Pending | N21: 3.3 | O21: Medium | R21: =IF(P21<>"",P21-D21,TODAY()-D21) | S21: Equipment delays
A22: E-010 | B22: Amanda Taylor | C22: Cohort 2 | D22: 46130 | E22: 46160 | F22: Pending | N22: 3.5 | O22: Low | R22: =IF(P22<>"",P22-D22,TODAY()-D22)

Sheet Risk Register
A1: RISK REGISTER
A2: Risk ID | B2: Category | C2: Description | D2: Likelihood | E2: Impact | F2: Risk Score | G2: Risk Level | H2: Owner | I2: Mitigation Strategy | J2: Contingency Plan | K2: Status | L2: Date Identified | M2: Target Resolution | N2: Days Open | O2: Trend | P2: Notes
A3: R-001 | B3: Security | C3: Clearance processing delays exceeding 90 days for Secret-level positions | D3: 4 | E3: 5 | F3: =D3*E3 | G3: =IF(F3>=20,"Critical",IF(F3>=12,"High",IF(F3>=6,"Medium","Low"))) | H3: FSO/Security | I3: Pre-submit eQIP packages; engage agency POC for status updates | J3: Request interim clearances for critical roles; reassign to non-cleared tasks | K3: Open | L3: 46106 | M3: 46203 | N3: =IF(K3="Closed",0,TODAY()-L3) | O3: Increasing | P3: Top risk
A4: R-002 | B4: Remote-Specific | C4: Remote workspace fails security requirements for CUI handling | D4: 3 | E4: 5 | F4: =D4*E4 | G4: =IF(F4>=20,"Critical",IF(F4>=12,"High",IF(F4>=6,"Medium","Low"))) | H4: FSO/Security | I4: Mandate workspace attestation before equipment shipment; conduct video verification | J4: Provide co-working space stipend at approved SCIFs | K4: Open | L4: 46106 | M4: 46157 | N4: =IF(K4="Closed",0,TODAY()-L4) | O4: Stable
A5: R-003 | B5: Technical | C5: VPN capacity insufficient for simultaneous remote connections | D5: 3 | E5: 4 | F5: =D5*E5 | G5: =IF(F5>=20,"Critical",IF(F5>=12,"High",IF(F5>=6,"Medium","Low"))) | H5: IT Lead | I5: Load test VPN before surge; procure additional licenses | J5: Deploy backup VPN gateway; stagger shift schedules | K5: Open | L5: 46107 | M5: 46143 | N5: =IF(K5="Closed",0,TODAY()-L5) | O5: Decreasing | P5: Capacity expanded
A6: R-004 | B6: Operational | C6: Equipment shipping delays due to supply chain disruptions | D6: 4 | E6: 4 | F6: =D6*E6 | G6: =IF(F6>=20,"Critical",IF(F6>=12,"High",IF(F6>=6,"Medium","Low"))) | H6: IT Lead | I6: Order 20% buffer stock; use multiple vendors; expedited shipping | J6: Loan personal devices with MDM enrollment temporarily | K6: Open | L6: 46107 | M6: 46157 | N6: =IF(K6="Closed",0,TODAY()-L6) | O6: Increasing
A7: R-005 | B7: Compliance | C7: Multi-state tax withholding and labor law compliance gaps | D7: 3 | E7: 4 | F7: =D7*E7 | G7: =IF(F7>=20,"Critical",IF(F7>=12,"High",IF(F7>=6,"Medium","Low"))) | H7: HR Manager | I7: Engage multi-state payroll provider; map employee locations to state requirements | J7: Contract with employment law firm for state-specific guidance | K7: Open | L7: 46108 | M7: 46172 | N7: =IF(K7="Closed",0,TODAY()-L7) | O7: Stable
A8: R-006 | B8: Personnel | C8: Attrition spike during first 30 days exceeding 15% threshold | D8: 4 | E8: 4 | F8: =D8*E8 | G8: =IF(F8>=20,"Critical",IF(F8>=12,"High",IF(F8>=6,"Medium","Low"))) | H8: HR Manager | I8: Implement structured onboarding; assign buddy mentors; conduct weekly check-ins | J8: Activate staffing agency rapid-fill agreements; maintain warm candidate bench | K8: Open | L8: 46108 | M8: 46157 | N8: =IF(K8="Closed",0,TODAY()-L8) | O8: Increasing | P8: 1 separation so far
A9: R-007 | B9: Operational | C9: Training bottleneck — insufficient trainer-to-trainee ratio | D9: 3 | E9: 3 | F9: =D9*E9 | G9: =IF(F9>=20,"Critical",IF(F9>=12,"High",IF(F9>=6,"Medium","Low"))) | H9: Training Lead | I9: Hire additional trainers; develop self-paced e-learning modules | J9: Deploy recorded training sessions; extend training timeline by 1 week | K9: Mitigating | L9: 46109 | M9: 46143 | N9: =IF(K9="Closed",0,TODAY()-L9) | O9: Stable | P9: Added e-learning
A10: R-008 | B10: Security | C10: Insider threat risk elevated with rapid onboarding of unknown personnel | D10: 3 | E10: 5 | F10: =D10*E10 | G10: =IF(F10>=20,"Critical",IF(F10>=12,"High",IF(F10>=6,"Medium","Low"))) | H10: FSO/Security | I10: Implement enhanced monitoring; enforce least-privilege access; UAM tools | J10: Immediate access revocation protocol; incident response plan activation | K10: Open | L10: 46109 | M10: 46203 | N10: =IF(K10="Closed",0,TODAY()-L10) | O10: Stable
A11: R-009 | B11: Compliance | C11: Data spill — CUI transmitted via unapproved channels by new hires | D11: 3 | E11: 5 | F11: =D11*E11 | G11: =IF(F11>=20,"Critical",IF(F11>=12,"High",IF(F11>=6,"Medium","Low"))) | H11: FSO/Security | I11: Mandatory CUI handling training before system access; DLP tools on endpoints | J11: Data spill response procedure; notify agency within 1 hour; contain and remediate | K11: Open | L11: 46110 | M11: 46203 | N11: =IF(K11="Closed",0,TODAY()-L11) | O11: Stable
A12: R-010 | B12: Security | C12: CUI handling violations in remote environments | D12: 3 | E12: 5 | F12: =D12*E12 | G12: =IF(F12>=20,"Critical",IF(F12>=12,"High",IF(F12>=6,"Medium","Low"))) | H12: FSO/Security | I12: Enforce endpoint encryption; disable USB ports; monitor print queues | J12: Remote workspace spot-check audits; retrain and re-certify | K12: Open | L12: 46110 | M12: 46203 | N12: =IF(K12="Closed",0,TODAY()-L12) | O12: Stable
A13: R-011 | B13: Security | C13: Interim clearance denials blocking critical role deployment | D13: 3 | E13: 4 | F13: =D13*E13 | G13: =IF(F13>=20,"Critical",IF(F13>=12,"High",IF(F13>=6,"Medium","Low"))) | H13: FSO/Security | I13: Pre-screen candidates for disqualifying factors; submit complete packages | J13: Reassign to non-sensitive roles; backfill with cleared personnel | K13: Open | L13: 46111 | M13: 46172 | N13: =IF(K13="Closed",0,TODAY()-L13) | O13: Stable
A14: R-012 | B14: Security | C14: Polygraph backlog delaying TS-SCI positions | D14: 4 | E14: 3 | F14: =D14*E14 | G14: =IF(F14>=20,"Critical",IF(F14>=12,"High",IF(F14>=6,"Medium","Low"))) | H14: FSO/Security | I14: Schedule polygraphs immediately upon offer acceptance; coordinate with agency | J14: Deploy to non-poly positions; request agency prioritization | K14: Open | L14: 46111 | M14: 46234 | N14: =IF(K14="Closed",0,TODAY()-L14) | O14: Increasing
A15: R-013 | B15: Compliance | C15: Foreign contact or foreign travel disclosures creating investigation delays | D15: 2 | E15: 4 | F15: =D15*E15 | G15: =IF(F15>=20,"Critical",IF(F15>=12,"High",IF(F15>=6,"Medium","Low"))) | H15: FSO/Security | I15: Pre-screen for foreign contacts during interview; prepare supplemental docs | J15: Assign to domestic-only, non-sensitive roles pending resolution | K15: Accepted | L15: 46112 | M15: 46203 | N15: =IF(K15="Closed",0,TODAY()-L15) | O15: Stable
A16: R-014 | B16: Operational | C16: Drug testing logistics — remote employees in areas without testing centers | D16: 3 | E16: 3 | F16: =D16*E16 | G16: =IF(F16>=20,"Critical",IF(F16>=12,"High",IF(F16>=6,"Medium","Low"))) | H16: HR Manager | I16: Map testing locations near each employee; mobile testing services | J16: Delay start dates until testing confirmed; virtual observed testing | K16: Mitigating | L16: 46112 | M16: 46157 | N16: =IF(K16="Closed",0,TODAY()-L16) | O16: Decreasing | P16: Mobile testing arranged
A17: R-015 | B17: Technical | C17: Badge/PIV provisioning delays for system access | D17: 3 | E17: 4 | F17: =D17*E17 | G17: =IF(F17>=20,"Critical",IF(F17>=12,"High",IF(F17>=6,"Medium","Low"))) | H17: IT Lead | I17: Pre-order blank PIV cards; coordinate with HSPD-12 enrollment stations | J17: Issue temporary credentials with limited access; extend enrollment hours | K17: Open | L17: 46113 | M17: 46172 | N17: =IF(K17="Closed",0,TODAY()-L17) | O17: Stable
A18: R-016 | B18: Compliance | C18: Social media screening revealing derogatory information post-hire | D18: 2 | E18: 3 | F18: =D18*E18 | G18: =IF(F18>=20,"Critical",IF(F18>=12,"High",IF(F18>=6,"Medium","Low"))) | H18: FSO/Security | I18: Conduct social media screening during pre-employment; document findings | J18: Suitability review board determination; separation if warranted | K18: Accepted | L18: 46113 | M18: 46203 | N18: =IF(K18="Closed",0,TODAY()-L18) | O18: Stable
A19: R-017 | B19: Security | C19: Reciprocity delays — prior clearances not transferring between agencies | D19: 3 | E19: 4 | F19: =D19*E19 | G19: =IF(F19>=20,"Critical",IF(F19>=12,"High",IF(F19>=6,"Medium","Low"))) | H19: FSO/Security | I19: Verify DISS/Scattered Castles records early; submit reciprocity requests immediately | J19: Request interim clearance; engage agency security office directly | K19: Open | L19: 46114 | M19: 46203 | N19: =IF(K19="Closed",0,TODAY()-L19) | O19: Stable
A20: R-018 | B20: Operational | C20: Lost or stolen equipment in transit or at remote locations | D20: 2 | E20: 4 | F20: =D20*E20 | G20: =IF(F20>=20,"Critical",IF(F20>=12,"High",IF(F20>=6,"Medium","Low"))) | H20: IT Lead | I20: Full disk encryption; asset tracking with GPS; signature-required delivery | J20: Remote wipe capability; file police report; replace within 48 hours | K20: Open | L20: 46114 | M20: 46203 | N20: =IF(K20="Closed",0,TODAY()-L20) | O20: Stable
A21: R-019 | B21: Remote-Specific | C21: Unauthorized telework locations — employees working from unapproved sites | D21: 3 | E21: 4 | F21: =D21*E21 | G21: =IF(F21>=20,"Critical",IF(F21>=12,"High",IF(F21>=6,"Medium","Low"))) | H21: HR Manager | I21: Require telework location approval; GPS check-in; random workspace audits | J21: Immediate VPN access suspension; formal counseling; potential separation | K21: Open | L21: 46115 | M21: 46172 | N21: =IF(K21="Closed",0,TODAY()-L21) | O21: Stable
A22: R-020 | B22: Personnel | C22: Quality degradation as new hires ramp up without adequate coaching | D22: 4 | E22: 4 | F22: =D22*E22 | G22: =IF(F22>=20,"Critical",IF(F22>=12,"High",IF(F22>=6,"Medium","Low"))) | H22: QA Lead | I22: Implement 100% monitoring during nesting; daily coaching sessions; buddy system | J22: Extend nesting period; remove from production; intensive remediation training | K22: Open | L22: 46115 | M22: 46157 | N22: =IF(K22="Closed",0,TODAY()-L22) | O22: Increasing | P22: Monitoring active

Sheet RACI Matrix
A1: RACI MATRIX — Surge Operations
A2: Task # | B2: Task Description | C2: Program Manager | D2: Recruiting Lead | E2: HR Manager | F2: FSO/Security | G2: IT Lead | H2: Training Lead | I2: QA Lead | J2: Supervisors | K2: Contracts | L2: Finance
A3: 1 | B3: Finalize surge headcount requirements | C3: R | D3: C | E3: C | F3: I | G3: I | H3: I | I3: I | J3: I | K3: A | L3: C
A4: 2 | B4: Submit staffing plan to COR | C4: R | D4: I | E4: I | F4: I | G4: I | H4: I | I4: I | J4: I | K4: A | L4: I
A5: 3 | B5: Define remote work policies | C5: A | D5: I | E5: R | F5: C | G5: C | H5: I | I5: I | J5: C | K5: I | L5: I
A6: 4 | B6: Post surge positions on job boards | C6: A | D6: R | E6: C | F6: I | G6: I | H6: I | I6: I | J6: I | K6: I | L6: I
A7: 5 | B7: Activate staffing agency contracts | C7: A | D7: R | E7: I | F7: I | G7: I | H7: I | I7: I | J7: I | K7: C | L7: R
A8: 6 | B8: Submit SAAR forms for system access | C8: I | D8: I | E8: I | F8: R | G8: C | H8: I | I8: I | J8: I | K8: A | L8: I
A9: 7 | B9: Order laptops and peripherals | C9: A | D9: I | E9: I | F9: I | G9: R | H9: I | I9: I | J9: I | K9: C | L9: C
A10: 8 | B10: Provision VPN accounts and MFA tokens | C10: I | D10: I | E10: I | F10: C | G10: R | H10: I | I10: I | J10: I | K10: I | L10: I
A11: 9 | B11: Develop virtual training curriculum | C11: A | D11: I | E11: I | F11: C | G11: C | H11: R | I11: C | J11: C | K11: I | L11: I
A12: 10 | B12: Prepare onboarding packets | C12: I | D12: C | E12: R | F12: C | G12: C | H12: C | I12: I | J12: C | K12: I | L12: I
A13: 11 | B13: Screen and interview candidates | C13: A | D13: R | E13: C | F13: I | G13: I | H13: I | I13: I | J13: C | K13: I | L13: I
... A40: 38 | B40: Process multi-state tax registrations | C40: I | D40: I | E40: R | F40: I | G40: I | H40: I | I40: I | J40: I | K40: C | L40: A

Sheet QA Monitoring
A1: QA MONITORING LOG
A2: Monitoring ID | B2: Date | C2: Employee ID | D2: Employee Name | E2: Supervisor | F2: Monitoring Type | G2: Communication | H2: Process Adherence | I2: Accuracy | J2: Compliance | K2: Customer Service | L2: System Navigation | M2: Documentation | N2: Weighted Score | O2: Pass/Fail | P2: Critical Error | Q2: Strengths | R2: Areas for Improvement | S2: Coaching Provided | T2: Team Average
A3: QA-001 | B3: 46126 | C3: E-001 | D3: Maria Santos | E3: T. Washington | F3: Live | G3: 5 | H3: 4 | I3: 5 | J3: 4 | K3: 5 | L3: 4 | M3: 4 | N3: =ROUND((G3*0.15+H3*0.15+I3*0.2+J3*0.15+K3*0.1+L3*0.1+M3*0.15)*20,1) | O3: =IF(N3>=80,"Pass","Fail") | P3: N | Q3: Excellent communication, empathetic tone | R3: Minor documentation gaps | S3: Y | T3: =ROUND(AVERAGE(N3:N27),1)
A4: QA-002 | B4: 46126 | C4: E-002 | D4: James Mitchell | E4: L. Chen | F4: Live | G4: 4 | H4: 4 | I4: 4 | J4: 4 | K4: 4 | L4: 3 | M4: 4 | N4: =ROUND((G4*0.15+H4*0.15+I4*0.2+J4*0.15+K4*0.1+L4*0.1+M4*0.15)*20,1) | O4: =IF(N4>=80,"Pass","Fail") | P4: N | Q4: Thorough and methodical | R4: System navigation speed | S4: Y | T4: Pass Rate
A5: QA-003 | B5: 46126 | C5: E-005 | D5: Priya Sharma | E5: L. Chen | F5: Recorded | G5: 3 | H5: 4 | I5: 4 | J5: 4 | K5: 3 | L5: 4 | M5: 3 | N5: =ROUND((G5*0.15+H5*0.15+I5*0.2+J5*0.15+K5*0.1+L5*0.1+M5*0.15)*20,1) | O5: =IF(N5>=80,"Pass","Fail") | P5: N | Q5: Accurate data entry | R5: Customer interaction needs coaching | S5: Y | T5: =COUNTIF(O3:O27,"Pass")/COUNTA(O3:O27)
A6: QA-004 | B6: 46127 | C6: E-011 | D6: Jason Parker | E6: L. Chen | F6: Live | G6: 4 | H6: 4 | I6: 4 | J6: 5 | K6: 4 | L6: 4 | M6: 4 | N6: =ROUND((G6*0.15+H6*0.15+I6*0.2+J6*0.15+K6*0.1+L6*0.1+M6*0.15)*20,1) | O6: =IF(N6>=80,"Pass","Fail") | P6: N | Q6: Good compliance awareness | R6: Documentation could be more detailed | S6: N | T6: D. Thompson
