Workbook

Sheet Dashboard
A1: Option C – Recruiting & Security Hub
A2: Government Contract Remote Surge Hiring Operation
A4: SUMMARY METRICS
A5: Metric | B5: Count | E5: Metric | F5: Count
A6: Total Candidates in Pipeline | B6: =COUNTA('Candidate Pipeline'!A2:A100)-COUNTBLANK('Candidate Pipeline'!A2:A100) | E6: Clearances Initiated | F6: =COUNTIF('Candidate Pipeline'!L2:L100,"Clearance Initiated")
A7: Interviews Scheduled | B7: =COUNTIF('Candidate Pipeline'!L2:L100,"Interview Scheduled") | E7: Clearances Pending | F7: =COUNTIF('e-QIP Tracker'!T2:T100,"Investigation Active")
A8: Interviews Completed | B8: =COUNTIF('Candidate Pipeline'!L2:L100,"Interviewed")+COUNTIF('Candidate Pipeline'!L2:L100,"Scored")+COUNTIF('Candidate Pipeline'!L2:L100,"Offer Extended")+COUNTIF('Candidate Pipeline'!L2:L100,"Offer Accepted")+COUNTIF('Candidate Pipeline'!L2:L100,"Clearance Initiated")+COUNTIF('Candidate Pipeline'!L2:L100,"Deployed") | E8: Clearances Granted | F8: =COUNTIF('e-QIP Tracker'!T2:T100,"Complete")
A9: Offers Extended | B9: =COUNTIF('Candidate Pipeline'!L2:L100,"Offer Extended") | E9: Clearances Denied | F9: =COUNTIF('e-QIP Tracker'!Y2:Y100,"Denied")
A10: Offers Accepted | B10: =COUNTIF('Candidate Pipeline'!L2:L100,"Offer Accepted")+COUNTIF('Candidate Pipeline'!L2:L100,"Clearance Initiated")+COUNTIF('Candidate Pipeline'!L2:L100,"Deployed")+COUNTIF('Candidate Pipeline'!L2:L100,"Clearance Pending")
A12: PIPELINE FUNNEL SUMMARY | F12: CLEARANCE STATUS BREAKDOWN
A13: Stage | B13: Count | C13: % of Total | F13: Status | G13: Count | H13: Avg Days in Status
A14: Sourced | B14: =COUNTIF('Candidate Pipeline'!L2:L100,A14) | C14: =IF(B$24=0,0,B14/B$24) | F14: Not Started | G14: =COUNTIF('e-QIP Tracker'!T2:T100,"Pre-Investigation")-COUNTIFS('e-QIP Tracker'!T2:T100,"Pre-Investigation",'e-QIP Tracker'!I2:I100,"<>"&"") | H14: N/A
A15: Screened | B15: =COUNTIF('Candidate Pipeline'!L2:L100,A15) | C15: =IF(B$24=0,0,B15/B$24) | F15: SF-86 In Progress | G15: =COUNTIFS('e-QIP Tracker'!O2:O100,"Pending Review") | H15: N/A
A16: Interview Scheduled | B16: =COUNTIF('Candidate Pipeline'!L2:L100,A16) | C16: =IF(B$24=0,0,B16/B$24) | F16: SF-86 Submitted | G16: =COUNTIFS('e-QIP Tracker'!O2:O100,"Approved")+COUNTIFS('e-QIP Tracker'!O2:O100,"Corrections Needed") | H16: N/A
A17: Interviewed | B17: =COUNTIF('Candidate Pipeline'!L2:L100,A17) | C17: =IF(B$24=0,0,B17/B$24) | F17: Investigation Active | G17: =COUNTIF('e-QIP Tracker'!T2:T100,"Investigation Active") | H17: N/A
A18: Scored | B18: =COUNTIF('Candidate Pipeline'!L2:L100,A18) | C18: =IF(B$24=0,0,B18/B$24) | F18: Interim Granted | G18: =COUNTIF('e-QIP Tracker'!W2:W100,"Granted") | H18: N/A
A19: Offer Extended | B19: =COUNTIF('Candidate Pipeline'!L2:L100,A19) | C19: =IF(B$24=0,0,B19/B$24) | F19: Final Granted | G19: =COUNTIF('e-QIP Tracker'!Y2:Y100,"Granted") | H19: N/A
A20: Offer Accepted | B20: =COUNTIF('Candidate Pipeline'!L2:L100,A20) | C20: =IF(B$24=0,0,B20/B$24) | F20: Denied/Withdrawn | G20: =COUNTIF('e-QIP Tracker'!Y2:Y100,"Denied")+COUNTIF('e-QIP Tracker'!Y2:Y100,"Withdrawn") | H20: N/A
A21: Clearance Initiated | B21: =COUNTIF('Candidate Pipeline'!L2:L100,A21) | C21: =IF(B$24=0,0,B21/B$24)
A22: Clearance Pending | B22: =COUNTIF('Candidate Pipeline'!L2:L100,A22) | C22: =IF(B$24=0,0,B22/B$24)
A23: Deployed | B23: =COUNTIF('Candidate Pipeline'!L2:L100,A23) | C23: =IF(B$24=0,0,B23/B$24)
A24: Total | B24: =COUNTA('Candidate Pipeline'!A2:A100)-COUNTBLANK('Candidate Pipeline'!A2:A100)
A27: RECRUITING VELOCITY METRICS
A28: Metric | B28: Value (Days)
A29: Avg Days Source-to-Offer | B29: =IFERROR(AVERAGE('Candidate Pipeline'!S2:S16-'Candidate Pipeline'!J2:J16),"N/A")
A30: Avg Days Offer-to-Clearance | B30: =IFERROR(AVERAGEIFS('e-QIP Tracker'!Z2:Z16,'e-QIP Tracker'!Z2:Z16,">0"),"N/A")
A31: Avg Days End-to-End | B31: =IFERROR(B29+B30,"N/A")
A33: Report generated: April 20, 2026 | Prepared by: Kelly | Plain Dealing, LA

Sheet Candidate Pipeline
A1: Candidate ID | B1: First Name | C1: Last Name | D1: Email | E1: Phone | F1: Source | G1: Position Title | H1: Labor Category | I1: Clearance Level Required | J1: Date Sourced | K1: Recruiter Assigned | L1: Current Stage | M1: Date Stage Updated | N1: Days in Current Stage | O1: Screening Notes | P1: Resume Received | Q1: Salary Expectation | R1: Offer Amount | S1: Offer Date | T1: Offer Accepted Date | U1: Start Date (Target) | V1: Disposition | W1: Disposition Reason | X1: Notes
A2: RC-1001 | B2: James | C2: Whitfield | D2: j.whitfield@email.com | E2: 318-555-0101 | F2: Referral | G2: IT Help Desk Specialist | H2: SCA-Help Desk II | I2: Public Trust | J2: 46082 | K2: Sarah Mitchell | L2: Clearance Initiated | M2: 46122 | N2: =IF(M2="","",TODAY()-M2) | O2: Strong Windows/AD experience | P2: Yes | Q2: 62000 | R2: 60000 | S2: 46109 | T2: 46112 | U2: 46157 | V2: Active | X2: Former contractor at DHS
A3: RC-1002 | B3: Maria | C3: Santos | D3: m.santos@email.com | E3: 504-555-0202 | F3: Job Board | G3: Systems Administrator | H3: IT-SysAdmin III | I3: Secret | J3: 46068 | K3: David Chen | L3: Clearance Pending | M3: 46101 | N3: =IF(M3="","",TODAY()-M3) | O3: Linux/RHEL certified, 8 yrs exp | P3: Yes | Q3: 95000 | R3: 92000 | S3: 46091 | T3: 46093 | U3: 46143 | V3: Active | X3: Currently holds interim Secret
A4: RC-1003 | B4: Robert | C4: Jackson | D4: r.jackson@email.com | E4: 225-555-0303 | F4: Agency | G4: Cybersecurity Analyst | H4: IT-Cyber II | I4: Top Secret | J4: 46091 | K4: Sarah Mitchell | L4: Interviewed | M4: 46127 | N4: =IF(M4="","",TODAY()-M4) | O4: CISSP certified, SOC experience | P4: Yes | Q4: 110000 | V4: Active | X4: Panel interview completed 4/15
A5: RC-1004 | B5: Tanya | C5: Brooks | D5: t.brooks@email.com | E5: 318-555-0404 | F5: Internal | G5: Program Analyst | H5: Analyst-Program II | I5: Public Trust | J5: 46086 | K5: David Chen | L5: Offer Extended | M5: 46124 | N5: =IF(M5="","",TODAY()-M5) | O5: PMP certified, strong comms | P5: Yes | Q5: 78000 | R5: 76000 | S5: 46124 | U5: 46162 | V5: Active | X5: Awaiting offer response
A6: RC-1005 | B6: Kevin | C6: Tran | D6: k.tran@email.com | E6: 713-555-0505 | F6: Job Board | G6: Network Engineer | H6: IT-Network III | I6: Secret | J6: 46073 | K6: Sarah Mitchell | L6: Deployed | M6: 46113 | N6: =IF(M6="","",TODAY()-M6) | O6: CCNP, 10 yrs federal exp | P6: Yes | Q6: 105000 | R6: 102000 | S6: 46086 | T6: 46088 | U6: 46113 | V6: Hired | X6: Onboarded successfully
A7: RC-1006 | B7: Diana | C7: Morris | D7: d.morris@email.com | E7: 501-555-0606 | F7: Referral | G7: Technical Writer | H7: Admin-TechWriter II | I7: Public Trust | J7: 46096 | K7: Lisa Park | L7: Screened | M7: 46113 | N7: =IF(M7="","",TODAY()-M7) | O7: DITA/XML expertise | P7: Yes | Q7: 65000 | V7: Active | X7: Needs interview scheduling
A8: RC-1007 | B8: Andre | C8: Williams | D8: a.williams@email.com | E8: 318-555-0707 | F8: Agency | G8: Database Administrator | H8: IT-DBA III | I8: TS-SCI | J8: 46042 | K8: David Chen | L8: Clearance Pending | M8: 46082 | N8: =IF(M8="","",TODAY()-M8) | O8: Oracle/PostgreSQL expert | P8: Yes | Q8: 120000 | R8: 115000 | S8: 46068 | T8: 46071 | U8: 46174 | V8: Active | X8: TS-SCI investigation in progress
A9: RC-1008 | B9: Jennifer | C9: Hawkins | D9: j.hawkins@email.com | E9: 214-555-0808 | F9: Job Board | G9: Project Manager | H9: PM-III | I9: Secret | J9: 46101 | K9: Lisa Park | L9: Interview Scheduled | M9: 46130 | N9: =IF(M9="","",TODAY()-M9) | O9: PMP, Agile certified | P9: Yes | Q9: 98000 | V9: Active | X9: Panel interview 4/22
A10: RC-1009 | B10: Carlos | C10: Rivera | D10: c.rivera@email.com | E10: 210-555-0909 | F10: Referral | G10: Service Desk Lead | H10: SCA-Help Desk III | I10: Public Trust | J10: 46106 | K10: Sarah Mitchell | L10: Scored | M10: 46128 | N10: =IF(M10="","",TODAY()-M10) | O10: ITIL v4, team lead exp | P10: Yes | Q10: 72000 | V10: Active | X10: Strong scores, ready for offer
A11: RC-1010 | B11: Patricia | C11: Nguyen | D11: p.nguyen@email.com | E11: 832-555-1010 | F11: Internal | G11: Quality Assurance Analyst | H11: IT-QA II | I11: Public Trust | J11: 46113 | K11: David Chen | L11: Sourced | M11: 46113 | N11: =IF(M11="","",TODAY()-M11) | P11: No | Q11: 70000 | V11: Active | X11: Internal transfer candidate
A12: RC-1011 | B12: Michael | C12: Foster | D12: m.foster@email.com | E12: 318-555-1111 | F12: Job Board | G12: Cloud Engineer | H12: IT-Cloud III | I12: Top Secret | J12: 46063 | K12: Lisa Park | L12: Withdrawn | M12: 46106 | N12: =IF(M12="","",TODAY()-M12) | O12: AWS Solutions Architect cert | P12: Yes | Q12: 130000 | R12: 125000 | S12: 46096 | V12: Withdrawn | W12: Accepted other offer | X12: Counter-offer not approved
A13: RC-1012 | B13: Angela | C13: Price | D13: a.price@email.com | E13: 504-555-1212 | F13: Agency | G13: Information Assurance Analyst | H13: IT-IA II | I13: Secret | J13: 46093 | K13: Sarah Mitchell | L13: Offer Accepted | M13: 46120 | N13: =IF(M13="","",TODAY()-M13) | O13: Security+ CE, RMF experience | P13: Yes | Q13: 88000 | R13: 85000 | S13: 46113 | T13: 46120 | U13: 46152 | V13: Active | X13: Initiating clearance process
A14: RC-1013 | B14: Thomas | C14: Clark | D14: t.clark@email.com | E14: 281-555-1313 | F14: Referral | G14: DevOps Engineer | H14: IT-DevOps III | I14: Secret | J14: 46099 | K14: David Chen | L14: Clearance Initiated | M14: 46127 | N14: =IF(M14="","",TODAY()-M14) | O14: Kubernetes/Docker, CI/CD pipelines | P14: Yes | Q14: 115000 | R14: 112000 | S14: 46117 | T14: 46119 | U14: 46172 | V14: Active | X14: e-QIP account created
A15: RC-1014 | B15: Samantha | C15: Reed | D15: s.reed@email.com | E15: 318-555-1414 | F15: Job Board | G15: Business Analyst | H15: Analyst-Business II | I15: Public Trust | J15: 46117 | K15: Lisa Park | L15: Screened | M15: 46122 | N15: =IF(M15="","",TODAY()-M15) | O15: Healthcare IT background | P15: Yes | Q15: 75000 | V15: Active | X15: Schedule technical interview
A16: RC-1015 | B16: William | C16: Thompson | D16: w.thompson@email.com | E16: 337-555-1515 | F16: Agency | G16: SOC Analyst | H16: IT-Cyber I | I16: Top Secret | J16: 46054 | K16: Sarah Mitchell | L16: Clearance Pending | M16: 46091 | N16: =IF(M16="","",TODAY()-M16) | O16: Splunk/SIEM, Sec+ certified | P16: Yes | Q16: 85000 | R16: 82000 | S16: 46078 | T16: 46081 | U16: 46157 | V16: Active | X16: Investigation active since 3/10

Sheet Interview Scorecard
A1: Candidate ID | B1: Candidate Name | C1: Position Title | D1: Interview Date | E1: Interview Type | F1: Interviewer Name | G1: Interviewer Role | H1: Technical Knowledge | I1: Communication Skills | J1: Problem Solving | K1: Customer Service Orientation | L1: Remote Work Readiness | M1: Government/Compliance Awareness | N1: Cultural Fit | O1: Weighted Total Score | P1: Overall Recommendation | Q1: Comments | R1: Red Flags | S1: Recommendation Notes
A2: RC-1001 | B2: James Whitfield | C2: IT Help Desk Specialist | D2: 46101 | E2: Phone Screen | F2: Sarah Mitchell | G2: Recruiter | H2: 4 | I2: 4 | J2: 3 | K2: 5 | L2: 4 | M2: 3 | N2: 4 | O2: =(H2*0.20+I2*0.10+J2*0.20+K2*0.10+L2*0.15+M2*0.15+N2*0.10) | P2: Strong Hire | Q2: Excellent customer service background | R2: None | S2: Recommend for next round
A3: RC-1001 | B3: James Whitfield | C3: IT Help Desk Specialist | D3: 46106 | E3: Technical | F3: Mark Reynolds | G3: Technical Lead | H3: 4 | I3: 4 | J3: 4 | K3: 5 | L3: 4 | M3: 3 | N3: 4 | O3: =(H3*0.20+I3*0.10+J3*0.20+K3*0.10+L3*0.15+M3*0.15+N3*0.10) | P3: Strong Hire | Q3: Solid AD/Windows troubleshooting skills | R3: None | S3: Ready for offer
A4: RC-1002 | B4: Maria Santos | C4: Systems Administrator | D4: 46082 | E4: Technical | F4: John Peters | G4: Sr. Systems Engineer | H4: 5 | I4: 4 | J4: 5 | K4: 3 | L4: 4 | M4: 4 | N4: 4 | O4: =(H4*0.20+I4*0.10+J4*0.20+K4*0.10+L4*0.15+M4*0.15+N4*0.10) | P4: Strong Hire | Q4: Deep Linux expertise, RHEL certified | R4: None | S4: Top candidate for SysAdmin role
A5: RC-1003 | B5: Robert Jackson | C5: Cybersecurity Analyst | D5: 46127 | E5: Panel | F5: Mark Reynolds | G5: Technical Lead | H5: 5 | I5: 3 | J5: 5 | K5: 3 | L5: 4 | M5: 5 | N5: 3 | O5: =(H5*0.20+I5*0.10+J5*0.20+K5*0.10+L5*0.15+M5*0.15+N5*0.10) | P5: Hire | Q5: Strong technical skills, quiet in panel | R5: Slightly reserved in group settings | S5: Solid hire, pair with mentor
A6: RC-1005 | B6: Kevin Tran | C6: Network Engineer | D6: 46081 | E6: Technical | F6: John Peters | G6: Sr. Systems Engineer | H6: 5 | I6: 5 | J6: 4 | K6: 4 | L6: 5 | M6: 5 | N6: 5 | O6: =(H6*0.20+I6*0.10+J6*0.20+K6*0.10+L6*0.15+M6*0.15+N6*0.10) | P6: Strong Hire | Q6: Outstanding federal networking experience | R6: None | S6: Fast-track for deployment
A7: RC-1005 | B7: Kevin Tran | C7: Network Engineer | D7: 46083 | E7: Final | F7: Laura Chen | G7: Program Manager | H7: 5 | I7: 5 | J7: 4 | K7: 4 | L7: 5 | M7: 5 | N7: 5 | O7: =(H7*0.20+I7*0.10+J7*0.20+K7*0.10+L7*0.15+M7*0.15+N7*0.10) | P7: Strong Hire | Q7: Excellent cultural fit, leadership potential | R7: None | S7: Extend offer immediately
A8: RC-1009 | B8: Carlos Rivera | C8: Service Desk Lead | D8: 46122 | E8: Phone Screen | F8: Lisa Park | G8: Recruiter | H8: 4 | I8: 5 | J8: 4 | K8: 5 | L8: 4 | M8: 3 | N8: 5 | O8: =(H8*0.20+I8*0.10+J8*0.20+K8*0.10+L8*0.15+M8*0.15+N8*0.10) | P8: Hire | Q8: Great leadership presence, ITIL background | R8: None | S8: Move to technical interview
A9: RC-1009 | B9: Carlos Rivera | C9: Service Desk Lead | D9: 46128 | E9: Technical | F9: Mark Reynolds | G9: Technical Lead | H9: 4 | I9: 5 | J9: 4 | K9: 5 | L9: 5 | M9: 4 | N9: 5 | O9: =(H9*0.20+I9*0.10+J9*0.20+K9*0.10+L9*0.15+M9*0.15+N9*0.10) | P9: Strong Hire | Q9: Demonstrated team management ability | R9: None | S9: Ready for offer stage
A10: RC-1011 | B10: Michael Foster | C10: Cloud Engineer | D10: 46091 | E10: Technical | F10: John Peters | G10: Sr. Systems Engineer | H10: 5 | I10: 3 | J10: 5 | K10: 3 | L10: 4 | M10: 4 | N10: 3 | O10: =(H10*0.20+I10*0.10+J10*0.20+K10*0.10+L10*0.15+M10*0.15+N10*0.10) | P10: Hire | Q10: Strong AWS skills but salary expectations high | R10: High salary demands | S10: Good technically, budget concern
A11: RC-1012 | B11: Angela Price | C11: Information Assurance Analyst | D11: 46109 | E11: Panel | F11: Mark Reynolds | G11: Technical Lead | H11: 4 | I11: 4 | J11: 4 | K11: 4 | L11: 4 | M11: 5 | N11: 4 | O11: =(H11*0.20+I11*0.10+J11*0.20+K11*0.10+L11*0.15+M11*0.15+N11*0.10) | P11: Hire | Q11: Solid RMF and NIST experience | R11: None | S11: Recommend for offer

Sheet e-QIP Tracker
A1: Candidate ID | B1: Employee Name | C1: SSN Last 4 | D1: Position Title | E1: Clearance Level Required | F1: Clearance Level Current | G1: Investigation Type | H1: FSO Assigned | I1: Date Candidate Notified | J1: e-QIP Account Created Date | K1: e-QIP Release Sent Date | L1: e-QIP Started by Candidate Date | M1: e-QIP Submitted by Candidate Date | N1: FSO Review Date | O1: FSO Review Status | P1: Corrections Requested | Q1: Corrections Details | R1: Date Submitted to DCSA | S1: DCSA Case Number | T1: Investigation Status | U1: Interim Clearance Requested | V1: Interim Clearance Date | W1: Interim Clearance Status | X1: Final Clearance Date | Y1: Final Clearance Status | Z1: Total Days in Process | AA1: Notes
A2: RC-1001 | B2: James Whitfield | C2: 4521 | D2: IT Help Desk Specialist | E2: Public Trust | F2: None | G2: T1 | H2: Rachel Foster | I2: 46113 | J2: 46115 | K2: 46115 | L2: 46117 | O2: Pending Review | P2: No | T2: Pre-Investigation | U2: No | Z2: =IF(I2="","",TODAY()-I2) | AA2: Candidate working on SF-86
A3: RC-1002 | B3: Maria Santos | C3: 7834 | D3: Systems Administrator | E3: Secret | F3: Interim Secret | G3: T3 | H3: Rachel Foster | I3: 46094 | J3: 46095 | K3: 46095 | L3: 46097 | M3: 46101 | N3: 46103 | O3: Submitted to DCSA | P3: No | R3: 46103 | S3: DCSA-2026-08821 | T3: Investigation Active | U3: Yes | V3: 46106 | W3: Granted | Z3: =IF(I3="","",TODAY()-I3) | AA3: Interim granted, investigation ongoing
A4: RC-1005 | B4: Kevin Tran | C4: 6190 | D4: Network Engineer | E4: Secret | F4: Secret | G4: T3 | H4: Tom Bradley | I4: 46089 | J4: 46090 | K4: 46090 | L4: 46091 | M4: 46093 | N4: 46095 | O4: Submitted to DCSA | P4: No | R4: 46095 | S4: DCSA-2026-07455 | T4: Complete | U4: No | X4: 46111 | Y4: Granted | Z4: =IF(I4="","",TODAY()-I4) | AA4: Final clearance granted, deployed
A5: RC-1007 | B5: Andre Williams | C5: 3347 | D5: Database Administrator | E5: TS-SCI | F5: Secret | G5: T5 | H5: Tom Bradley | I5: 46073 | J5: 46074 | K5: 46074 | L5: 46077 | M5: 46082 | N5: 46084 | O5: Submitted to DCSA | P5: Yes | Q5: Foreign travel dates corrected | R5: 46086 | S5: DCSA-2026-06230 | T5: Investigation Active | U5: Yes | V5: 46091 | W5: Granted | Z5: =IF(I5="","",TODAY()-I5) | AA5: Full TS-SCI investigation in progress
A6: RC-1012 | B6: Angela Price | C6: 8856 | D6: Information Assurance Analyst | E6: Secret | F6: None | G6: T3 | H6: Rachel Foster | I6: 46121 | J6: 46122 | K6: 46122 | L6: 46124 | O6: Pending Review | P6: No | T6: Pre-Investigation | U6: No | Z6: =IF(I6="","",TODAY()-I6) | AA6: SF-86 in progress
A7: RC-1013 | B7: Thomas Clark | C7: 2298 | D7: DevOps Engineer | E7: Secret | F7: None | G7: T3 | H7: Tom Bradley | I7: 46120 | J7: 46122 | K7: 46122 | L7: 46126 | O7: Pending Review | P7: No | T7: Pre-Investigation | U7: Yes | W7: Pending | Z7: =IF(I7="","",TODAY()-I7) | AA7: Just started e-QIP
A8: RC-1015 | B8: William Thompson | C8: 5573 | D8: SOC Analyst | E8: Top Secret | F8: None | G8: T5 | H8: Tom Bradley | I8: 46082 | J8: 46083 | K8: 46083 | L8: 46085 | M8: 46089 | N8: 46091 | O8: Submitted to DCSA | P8: Yes | Q8: Employment gap clarification | R8: 46093 | S8: DCSA-2026-07100 | T8: Investigation Active | U8: Yes | W8: Pending | Z8: =IF(I8="","",TODAY()-I8) | AA8: Awaiting interim decision
A9: RC-1003 | B9: Robert Jackson | C9: 9012 | D9: Cybersecurity Analyst | E9: Top Secret | F9: None | G9: T5 | H9: Rachel Foster | P9: No | T9: Pre-Investigation | U9: No | Z9: =IF(I9="","",TODAY()-I9) | AA9: Pending interview completion
A10: RC-1004 | B10: Tanya Brooks | C10: 1147 | D10: Program Analyst | E10: Public Trust | F10: None | G10: T1 | H10: Rachel Foster | P10: No | T10: Pre-Investigation | U10: No | Z10: =IF(I10="","",TODAY()-I10) | AA10: Awaiting offer acceptance
A11: RC-1006 | B11: Diana Morris | C11: 6633 | D11: Technical Writer | E11: Public Trust | F11: None | G11: T1 | H11: Tom Bradley | P11: No | T11: Pre-Investigation | U11: No | Z11: =IF(I11="","",TODAY()-I11) | AA11: Not yet in clearance pipeline
A12: RC-1008 | B12: Jennifer Hawkins | C12: 4401 | D12: Project Manager | E12: Secret | F12: None | G12: T3 | H12: Rachel Foster | P12: No | T12: Pre-Investigation | U12: No | Z12: =IF(I12="","",TODAY()-I12) | AA12: Interview pending
A13: RC-1009 | B13: Carlos Rivera | C13: 7789 | D13: Service Desk Lead | E13: Public Trust | F13: None | G13: T1 | H13: Tom Bradley | P13: No | T13: Pre-Investigation | U13: No | Z13: =IF(I13="","",TODAY()-I13) | AA13: Scoring complete, pending offer
A14: RC-1010 | B14: Patricia Nguyen | C14: 2255 | D14: Quality Assurance Analyst | E14: Public Trust | F14: None | G14: T1 | H14: Rachel Foster | P14: No | T14: Pre-Investigation | U14: No | Z14: =IF(I14="","",TODAY()-I14) | AA14: Early pipeline stage
A15: RC-1011 | B15: Michael Foster | C15: 8814 | D15: Cloud Engineer | E15: Top Secret | F15: None | G15: T5 | H15: Tom Bradley | P15: No | T15: Pre-Investigation | U15: No | Z15: =IF(I15="","",TODAY()-I15) | AA15: Candidate withdrawn
A16: RC-1014 | B16: Samantha Reed | C16: 3367 | D16: Business Analyst | E16: Public Trust | F16: None | G16: T1 | H16: Rachel Foster | P16: No | T16: Pre-Investigation | U16: No | Z16: =IF(I16="","",TODAY()-I16) | AA16: Early pipeline, screening phase

Sheet e-QIP Document Checklist
A1: Candidate ID | B1: Candidate Name | C1: Document Type | D1: Required | E1: Received | F1: Date Received | G1: Verified By | H1: Notes
A2: RC-1001 | B2: James Whitfield | C2: SF-86 Questionnaire | D2: Yes | E2: Yes | F2: 46117 | G2: Rachel Foster | H2: Complete
A3: RC-1001 | B3: James Whitfield | C3: Release Forms (Authorization & HIPAA) | D3: Yes | E3: Yes | F3: 46117 | G3: Rachel Foster | H3: Signed
A4: RC-1001 | B4: James Whitfield | C4: Fingerprint Cards (FD-258) | D4: Yes | E4: Yes | F4: 46118 | G4: Rachel Foster
A5: RC-1001 | B5: James Whitfield | C5: Birth Certificate or Passport | D5: Yes | E5: Yes | F5: 46116 | G5: Rachel Foster | H5: Passport provided
A6: RC-1001 | B6: James Whitfield | C6: Social Security Card | D6: Yes | E6: Yes | F6: 46116 | G6: Rachel Foster
A7: RC-1001 | B7: James Whitfield | C7: Driver's License | D7: Yes | E7: Yes | F7: 46116 | G7: Rachel Foster
A8: RC-1001 | B8: James Whitfield | C8: Employment History (10 years) | D8: Yes | E8: Yes | F8: 46117 | G8: Rachel Foster | H8: 10 year history verified
A9: RC-1001 | B9: James Whitfield | C9: Education Transcripts | D9: Yes | E9: No | H9: Awaiting transcripts from LSU
A10: RC-1001 | B10: James Whitfield | C10: Residence History (10 years) | D10: Yes | E10: Yes | F10: 46117 | G10: Rachel Foster
A11: RC-1001 | B11: James Whitfield | C11: Reference Contact List (min 3) | D11: Yes | E11: Yes | F11: 46117 | G11: Rachel Foster | H11: 3 references provided
A12: RC-1001 | B12: James Whitfield | C12: Financial Disclosure | D12: Yes | E12: No | H12: Requested from candidate
A13: RC-1001 | B13: James Whitfield | C13: Foreign Travel Records | D13: Yes | E13: No | H13: N/A per candidate
A14: RC-1001 | B14: James Whitfield | C14: Military Records (if applicable) | D14: No | E14: No | H14: Not applicable
A15: RC-1001 | B15: James Whitfield | C15: Court Records (if applicable) | D15: No | E15: No | H15: Not applicable
A16: RC-1001 | B16: James Whitfield | C16: Credit Report Authorization | D16: Yes | E16: Yes | F16: 46117 | G16: Rachel Foster | H16: Signed
A17: RC-1002 | B17: Maria Santos | C17: SF-86 Questionnaire | D17: Yes | E17: Yes | F17: 46096 | G17: Rachel Foster | H17: Complete
A18: RC-1002 | B18: Maria Santos | C18: Release Forms (Authorization & HIPAA) | D18: Yes | E18: Yes | F18: 46096 | G18: Rachel Foster | H18: Signed
A19: RC-1002 | B19: Maria Santos | C19: Fingerprint Cards (FD-258) | D19: Yes | E19: Yes | F19: 46097 | G19: Rachel Foster
A20: RC-1002 | B20: Maria Santos | C20: Birth Certificate or Passport | D20: Yes | E20: Yes | F20: 46096 | G20: Rachel Foster | H20: Birth certificate
A21: RC-1002 | B21: Maria Santos | C21: Social Security Card | D21: Yes | E21: Yes | F21: 46096 | G21: Rachel Foster
A22: RC-1002 | B22: Maria Santos | C22: Driver's License | D22: Yes | E22: Yes | F22: 46096 | G22: Rachel Foster
A23: RC-1002 | B23: Maria Santos | C23: Employment History (10 years) | D23: Yes | E23: Yes | F23: 46097 | G23: Rachel Foster | H23: Verified
A24: RC-1002 | B24: Maria Santos | C24: Education Transcripts | D24: Yes | E24: Yes | F24: 46097 | G24: Rachel Foster | H24: BS Computer Science
A25: RC-1002 | B25: Maria Santos | C25: Residence History (10 years) | D25: Yes | E25: Yes | F25: 46097 | G25: Rachel Foster
A26: RC-1002 | B26: Maria Santos | C26: Reference Contact List (min 3) | D26: Yes | E26: Yes | F26: 46097 | G26: Rachel Foster | H26: 4 references
A27: RC-1002 | B27: Maria Santos | C27: Financial Disclosure | D27: Yes | E27: Yes | F27: 46098 | G27: Rachel Foster
A28: RC-1002 | B28: Maria Santos | C28: Foreign Travel Records | D28: Yes | E28: Yes | F28: 46098 | G28: Rachel Foster | H28: No foreign travel
A29: RC-1002 | B29: Maria Santos | C29: Military Records (if applicable) | D29: No | E29: No | H29: Not applicable
A30: RC-1002 | B30: Maria Santos | C30: Court Records (if applicable) | D30: No | E30: No | H30: Not applicable
A31: RC-1002 | B31: Maria Santos | C31: Credit Report Authorization | D31: Yes | E31: Yes | F31: 46096 | G31: Rachel Foster | H31: Signed
A32: RC-1007 | B32: Andre Williams | C32: SF-86 Questionnaire | D32: Yes | E32: Yes | F32: 46077 | G32: Tom Bradley | H32: Complete - corrected
A33: RC-1007 | B33: Andre Williams | C33: Release Forms (Authorization & HIPAA) | D33: Yes | E33: Yes | F33: 46077 | G33: Tom Bradley | H33: Signed
A34: RC-1007 | B34: Andre Williams | C34: Fingerprint Cards (FD-258) | D34: Yes | E34: Yes | F34: 46078 | G34: Tom Bradley
A35: RC-1007 | B35: Andre Williams | C35: Birth Certificate or Passport | D35: Yes | E35: Yes | F35: 46077 | G35: Tom Bradley | H35: Passport
A36: RC-1007 | B36: Andre Williams | C36: Social Security Card | D36: Yes | E36: Yes | F36: 46077 | G36: Tom Bradley
A37: RC-1007 | B37: Andre Williams | C37: Driver's License | D37: Yes | E37: Yes | F37: 46077 | G37: Tom Bradley
A38: RC-1007 | B38: Andre Williams | C38: Employment History (10 years) | D38: Yes | E38: Yes | F38: 46078 | G38: Tom Bradley | H38: Verified
A39: RC-1007 | B39: Andre Williams | C39: Education Transcripts | D39: Yes | E39: Yes | F39: 46078 | G39: Tom Bradley | H39: MS IT
A40: RC-1007 | B40: Andre Williams | C40: Residence History (10 years) | D40: Yes | E40: Yes | F40: 46078 | G40: Tom Bradley
...

Sheet Recruiting Checklist
A1: Phase | B1: Task # | C1: Task Description | D1: Owner | E1: Target Date | F1: Actual Date | G1: Status | H1: Priority | I1: Dependencies | J1: Notes
A2: Phase 1 - Pre-Surge Prep | B2: 1.1 | C2: Confirm labor category requirements | D2: Kelly | E2: 46054 | F2: 46054 | G2: Complete | H2: High | J2: All 8 labor categories confirmed
A3: Phase 1 - Pre-Surge Prep | B3: 1.2 | C3: Validate position descriptions | D3: Kelly | E3: 46058 | F3: 46057 | G3: Complete | H3: High | I3: 1.1 | J3: PDs aligned with PWS
A4: Phase 1 - Pre-Surge Prep | B4: 1.3 | C4: Set up recruiting accounts/postings | D4: Lisa Park | E4: 46063 | F4: 46063 | G4: Complete | H4: High | I4: 1.2 | J4: Indeed, ClearanceJobs, USAJOBS
A5: Phase 1 - Pre-Surge Prep | B5: 1.4 | C5: Brief recruiting team | D5: Kelly | E5: 46065 | F5: 46065 | G5: Complete | H5: High | I5: 1.2 | J5: All recruiters briefed on surge requirements
A6: Phase 1 - Pre-Surge Prep | B6: 1.5 | C6: Establish candidate evaluation criteria | D6: Sarah Mitchell | E6: 46067 | F6: 46067 | G6: Complete | H6: High | I6: 1.1 | J6: Scorecard template finalized
A7: Phase 1 - Pre-Surge Prep | B7: 1.6 | C7: Confirm clearance requirements by position | D7: Rachel Foster | E7: 46067 | F7: 46068 | G7: Complete | H7: High | I7: 1.1 | J7: PT/Secret/TS/TS-SCI mapped
A8: Phase 1 - Pre-Surge Prep | B8: 1.7 | C8: Coordinate with FSO on clearance processing capacity | D8: Tom Bradley | E8: 46071 | F8: 46071 | G8: Complete | H8: Medium | I8: 1.6 | J8: FSO can handle 10 concurrent submissions
A9: Phase 2 - Active Recruiting | B9: 2.1 | C9: Post positions to job boards | D9: Lisa Park | E9: 46073 | F9: 46073 | G9: Complete | H9: High | I9: 1.3 | J9: 12 positions posted
A10: Phase 2 - Active Recruiting | B10: 2.2 | C10: Activate agency partnerships | D10: David Chen | E10: 46075 | F10: 46075 | G10: Complete | H10: High | J10: 3 agencies engaged
A11: Phase 2 - Active Recruiting | B11: 2.3 | C11: Begin candidate sourcing | D11: Sarah Mitchell | E11: 46078 | F11: 46078 | G11: Complete | H11: High | I11: 2.1, 2.2 | J11: Active sourcing across all channels
A12: Phase 2 - Active Recruiting | B12: 2.4 | C12: Screen resumes against requirements | D12: Lisa Park | E12: 46082 | F12: 46082 | G12: In Progress | H12: High | I12: 2.3 | J12: Ongoing as candidates apply
A13: Phase 2 - Active Recruiting | B13: 2.5 | C13: Schedule phone screens | D13: Sarah Mitchell | E13: 46086 | F13: 46086 | G13: In Progress | H13: High | I13: 2.4 | J13: Rolling schedule
A14: Phase 2 - Active Recruiting | B14: 2.6 | C14: Conduct interviews | D14: Mark Reynolds | E14: 46091 | F14: 46091 | G14: In Progress | H14: High | I14: 2.5 | J14: Technical and panel interviews ongoing
A15: Phase 2 - Active Recruiting | B15: 2.7 | C15: Score candidates on Interview Scorecard | D15: Mark Reynolds | E15: 46091 | F15: 46093 | G15: In Progress | H15: High | I15: 2.6 | J15: 10 scored to date
A16: Phase 2 - Active Recruiting | B16: 2.8 | C16: Check references | D16: David Chen | E16: 46096 | F16: 46096 | G16: In Progress | H16: Medium | I16: 2.6 | J16: Completed for top candidates
A17: Phase 3 - Selection & Offers | B17: 3.1 | C17: Rank candidates by score | D17: Kelly | E17: 46101 | F17: 46101 | G17: In Progress | H17: High | I17: 2.7 | J17: Updated weekly
A18: Phase 3 - Selection & Offers | B18: 3.2 | C18: Select top candidates | D18: Kelly | E18: 46103 | F18: 46103 | G18: In Progress | H18: High | I18: 3.1 | J18: Selection committee review
A19: Phase 3 - Selection & Offers | B19: 3.3 | C19: Generate offer letters | D19: Lisa Park | E19: 46106 | F19: 46106 | G19: In Progress | H19: High | I19: 3.2 | J19: Template approved by contracts
A20: Phase 3 - Selection & Offers | B20: 3.4 | C20: Extend offers | D20: Kelly | E20: 46109 | F20: 46109 | G20: In Progress | H20: High | I20: 3.3 | J20: 6 offers extended to date
A21: Phase 3 - Selection & Offers | B21: 3.5 | C21: Track offer acceptances | D21: Sarah Mitchell | E21: 46113 | G21: In Progress | H21: High | I21: 3.4 | J21: 4 accepted, 1 pending, 1 declined
A22: Phase 3 - Selection & Offers | B22: 3.6 | C22: Initiate e-QIP for accepted candidates | D22: Rachel Foster | E22: 46117 | G22: In Progress | H22: High | I22: 3.5 | J22: Coordinating with FSO
A23: Phase 3 - Selection & Offers | B23: 3.7 | C23: Brief candidates on clearance process | D23: Tom Bradley | E23: 46119 | G23: In Progress | H23: Medium | I23: 3.6 | J23: Standard briefing packet sent
A24: Phase 4 - Clearance Processing | B24: 4.1 | C24: Create e-QIP accounts | D24: Rachel Foster | E24: 46122 | F24: 46122 | G24: In Progress | H24: High | I24: 3.6 | J24: 5 accounts created
A25: Phase 4 - Clearance Processing | B25: 4.2 | C25: Send e-QIP release emails | D25: Rachel Foster | E25: 46122 | F25: 46122 | G25: In Progress | H25: High | I25: 4.1 | J25: Releases sent to all active candidates
A26: Phase 4 - Clearance Processing | B26: 4.3 | C26: Monitor candidate e-QIP progress | D26: Tom Bradley | E26: 46127 | G26: In Progress | H26: High | I26: 4.2 | J26: Daily check-ins with candidates
A27: Phase 4 - Clearance Processing | B27: 4.4 | C27: FSO review submissions | D27: Tom Bradley | E27: 46132 | G27: In Progress | H27: High | I27: 4.3 | J27: 2 reviewed, 3 pending
A28: Phase 4 - Clearance Processing | B28: 4.5 | C28: Submit to DCSA | D28: Tom Bradley | E28: 46134 | G28: Not Started | H28: High | I28: 4.4 | J28: Awaiting FSO reviews
A29: Phase 4 - Clearance Processing | B29: 4.6 | C29: Track investigation status | D29: Rachel Foster | E29: 46137 | G29: In Progress | H29: Medium | I29: 4.5 | J29: 3 active investigations
A30: Phase 4 - Clearance Processing | B30: 4.7 | C30: Process interim clearances | D30: Tom Bradley | E30: 46140 | G30: In Progress | H30: High | I30: 4.5 | J30: 2 interim clearances granted
A31: Phase 4 - Clearance Processing | B31: 4.8 | C31: Follow up on stalled investigations | D31: Rachel Foster | E31: 46143 | G31: Not Started | H31: Medium | I31: 4.6 | J31: No stalls yet identified

Sheet Alerts & Action Items
A1: Alert Date | B1: Category | C1: Priority | D1: Description | E1: Related Candidate ID | F1: Owner | G1: Due Date | H1: Status | I1: Resolution Notes
A2: 46132 | B2: Pipeline | C2: Critical | D2: Candidate stalled in Screened stage >14 days - no interview scheduled | E2: RC-1006 | F2: Lisa Park | G2: 46134 | H2: Open
A3: 46132 | B3: Clearance | C3: Critical | D3: e-QIP corrections overdue - candidate notified 3/1 but no update since 3/10 | E3: RC-1015 | F3: Tom Bradley | G3: 46133 | H3: Open
A4: 46132 | B4: Pipeline | C4: High | D4: Offer response pending >8 days - follow up required | E4: RC-1004 | F4: Kelly | G4: 46133 | H4: Open
A5: 46130 | B5: Interview | C5: High | D5: Interview not scheduled within 5 days of screening completion | E5: RC-1014 | F5: Lisa Park | G5: 46132 | H5: In Progress | I5: Phone screen being scheduled for 4/22
A6: 46130 | B6: Document | C6: High | D6: Missing required clearance documents - 3 items outstanding | E6: RC-1013 | F6: Tom Bradley | G6: 46137 | H6: Open
A7: 46127 | B7: Clearance | C7: High | D7: Interim clearance request pending >30 days with no decision | E7: RC-1015 | F7: Tom Bradley | G7: 46134 | H7: Open
A8: 46127 | B8: Document | C8: Medium | D8: Education transcripts not received - requested 4/5 | E8: RC-1001 | F8: Rachel Foster | G8: 46137 | H8: Open
A9: 46126 | B9: Pipeline | C9: Medium | D9: Candidate scored but no offer action taken within 5 business days | E9: RC-1009 | F9: Kelly | G9: 46133 | H9: Open
A10: 46122 | B10: Clearance | C10: Medium | D10: e-QIP started but not submitted by candidate within 7 days | E10: RC-1001 | F10: Rachel Foster | G10: 46129 | H10: In Progress | I10: Candidate reports 80% complete
A11: 46113 | B11: Checklist | C11: Medium | D11: Phase 4 clearance processing tasks behind schedule | F11: Tom Bradley | G11: 46127 | H11: Resolved | I11: Caught up as of 4/15
